{
  "contract": "PB-VOXEL-CHAR-v1",
  "schemaVersion": "0.1.0",
  "id": "void-scholar-voxel-v1",
  "bytecode": "PB-VOXEL-CHAR-v1-VOID-SCHOLAR-RESONANT",
  "dimensions": {
    "width": 18,
    "height": 34,
    "depth": 10
  },
  "materials": {
    "1": {
      "id": "voidLeather",
      "role": "outline-hair-boots",
      "colorHint": "#171021"
    },
    "2": {
      "id": "scholarRobe",
      "role": "robe-body-dark-violet",
      "colorHint": "#241a3f"
    },
    "3": {
      "id": "goldArmor",
      "role": "armor-inlay-bracers-belt-clasp",
      "colorHint": "#f6b863"
    },
    "4": {
      "id": "psychicGlow",
      "role": "eyes-halo-lattice",
      "colorHint": "#d9fbff"
    },
    "5": {
      "id": "warmSkin",
      "role": "skin-hands-face-only",
      "colorHint": "#c98f45"
    }
  },
  "voxels": [
    {
      "x": 5,
      "y": 0,
      "z": 3,
      "materialId": 1,
      "energy": 0.1,
      "energyType": 2
    },
    {
      "x": 6,
      "y": 0,
      "z": 3,
      "materialId": 1,
      "energy": 0.1,
      "energyType": 2
    },
    {
      "x": 7,
      "y": 0,
      "z": 3,
      "materialId": 1,
      "energy": 0.1,
      "energyType": 2
    },
    {
      "x": 10,
      "y": 0,
      "z": 3,
      "materialId": 1,
      "energy": 0.1,
      "energyType": 2
    },
    {
      "x": 11,
      "y": 0,
      "z": 3,
      "materialId": 1,
      "energy": 0.1,
      "energyType": 2
    },
    {
      "x": 12,
      "y": 0,
      "z": 3,
      "materialId": 1,
      "energy": 0.1,
      "energyType": 2
    },
    {
      "x": 5,
      "y": 0,
      "z": 4,
      "materialId": 1,
      "energy": 0.1,
      "energyType": 2
    },
    {
      "x": 6,
      "y": 0,
      "z": 4,
      "materialId": 1,
      "energy": 0.1,
      "energyType": 2
    },
    {
      "x": 7,
      "y": 0,
      "z": 4,
      "materialId": 1,
      "energy": 0.1,
      "energyType": 2
    },
    {
      "x": 10,
      "y": 0,
      "z": 4,
      "materialId": 1,
      "energy": 0.1,
      "energyType": 2
    },
    {
      "x": 11,
      "y": 0,
      "z": 4,
      "materialId": 1,
      "energy": 0.1,
      "energyType": 2
    },
    {
      "x": 12,
      "y": 0,
      "z": 4,
      "materialId": 1,
      "energy": 0.1,
      "energyType": 2
    },
    {
      "x": 4,
      "y": 0,
      "z": 5,
      "materialId": 1,
      "energy": 0.1,
      "energyType": 2
    },
    {
      "x": 5,
      "y": 0,
      "z": 5,
      "materialId": 1,
      "energy": 0.1,
      "energyType": 2
    },
    {
      "x": 6,
      "y": 0,
      "z": 5,
      "materialId": 1,
      "energy": 0.1,
      "energyType": 2
    },
    {
      "x": 7,
      "y": 0,
      "z": 5,
      "materialId": 1,
      "energy": 0.1,
      "energyType": 2
    },
    {
      "x": 10,
      "y": 0,
      "z": 5,
      "materialId": 1,
      "energy": 0.1,
      "energyType": 2
    },
    {
      "x": 11,
      "y": 0,
      "z": 5,
      "materialId": 1,
      "energy": 0.1,
      "energyType": 2
    },
    {
      "x": 12,
      "y": 0,
      "z": 5,
      "materialId": 1,
      "energy": 0.1,
      "energyType": 2
    },
    {
      "x": 13,
      "y": 0,
      "z": 5,
      "materialId": 1,
      "energy": 0.1,
      "energyType": 2
    },
    {
      "x": 4,
      "y": 0,
      "z": 6,
      "materialId": 1,
      "energy": 0.1,
      "energyType": 2
    },
    {
      "x": 5,
      "y": 0,
      "z": 6,
      "materialId": 1,
      "energy": 0.1,
      "energyType": 2
    },
    {
      "x": 6,
      "y": 0,
      "z": 6,
      "materialId": 1,
      "energy": 0.1,
      "energyType": 2
    },
    {
      "x": 7,
      "y": 0,
      "z": 6,
      "materialId": 1,
      "energy": 0.1,
      "energyType": 2
    },
    {
      "x": 10,
      "y": 0,
      "z": 6,
      "materialId": 1,
      "energy": 0.1,
      "energyType": 2
    },
    {
      "x": 11,
      "y": 0,
      "z": 6,
      "materialId": 1,
      "energy": 0.1,
      "energyType": 2
    },
    {
      "x": 12,
      "y": 0,
      "z": 6,
      "materialId": 1,
      "energy": 0.1,
      "energyType": 2
    },
    {
      "x": 13,
      "y": 0,
      "z": 6,
      "materialId": 1,
      "energy": 0.1,
      "energyType": 2
    },
    {
      "x": 4,
      "y": 0,
      "z": 7,
      "materialId": 1,
      "energy": 0.1,
      "energyType": 2
    },
    {
      "x": 5,
      "y": 0,
      "z": 7,
      "materialId": 1,
      "energy": 0.1,
      "energyType": 2
    },
    {
      "x": 6,
      "y": 0,
      "z": 7,
      "materialId": 1,
      "energy": 0.1,
      "energyType": 2
    },
    {
      "x": 7,
      "y": 0,
      "z": 7,
      "materialId": 1,
      "energy": 0.1,
      "energyType": 2
    },
    {
      "x": 10,
      "y": 0,
      "z": 7,
      "materialId": 1,
      "energy": 0.1,
      "energyType": 2
    },
    {
      "x": 11,
      "y": 0,
      "z": 7,
      "materialId": 1,
      "energy": 0.1,
      "energyType": 2
    },
    {
      "x": 12,
      "y": 0,
      "z": 7,
      "materialId": 1,
      "energy": 0.1,
      "energyType": 2
    },
    {
      "x": 13,
      "y": 0,
      "z": 7,
      "materialId": 1,
      "energy": 0.1,
      "energyType": 2
    },
    {
      "x": 5,
      "y": 1,
      "z": 3,
      "materialId": 1,
      "energy": 0.1,
      "energyType": 2
    },
    {
      "x": 6,
      "y": 1,
      "z": 3,
      "materialId": 1,
      "energy": 0.1,
      "energyType": 2
    },
    {
      "x": 7,
      "y": 1,
      "z": 3,
      "materialId": 1,
      "energy": 0.1,
      "energyType": 2
    },
    {
      "x": 10,
      "y": 1,
      "z": 3,
      "materialId": 1,
      "energy": 0.1,
      "energyType": 2
    },
    {
      "x": 11,
      "y": 1,
      "z": 3,
      "materialId": 1,
      "energy": 0.1,
      "energyType": 2
    },
    {
      "x": 12,
      "y": 1,
      "z": 3,
      "materialId": 1,
      "energy": 0.1,
      "energyType": 2
    },
    {
      "x": 5,
      "y": 1,
      "z": 4,
      "materialId": 1,
      "energy": 0.1,
      "energyType": 2
    },
    {
      "x": 6,
      "y": 1,
      "z": 4,
      "materialId": 1,
      "energy": 0.1,
      "energyType": 2
    },
    {
      "x": 7,
      "y": 1,
      "z": 4,
      "materialId": 1,
      "energy": 0.1,
      "energyType": 2
    },
    {
      "x": 10,
      "y": 1,
      "z": 4,
      "materialId": 1,
      "energy": 0.1,
      "energyType": 2
    },
    {
      "x": 11,
      "y": 1,
      "z": 4,
      "materialId": 1,
      "energy": 0.1,
      "energyType": 2
    },
    {
      "x": 12,
      "y": 1,
      "z": 4,
      "materialId": 1,
      "energy": 0.1,
      "energyType": 2
    },
    {
      "x": 4,
      "y": 1,
      "z": 5,
      "materialId": 1,
      "energy": 0.1,
      "energyType": 2
    },
    {
      "x": 5,
      "y": 1,
      "z": 5,
      "materialId": 1,
      "energy": 0.1,
      "energyType": 2
    },
    {
      "x": 6,
      "y": 1,
      "z": 5,
      "materialId": 1,
      "energy": 0.1,
      "energyType": 2
    },
    {
      "x": 7,
      "y": 1,
      "z": 5,
      "materialId": 1,
      "energy": 0.1,
      "energyType": 2
    },
    {
      "x": 10,
      "y": 1,
      "z": 5,
      "materialId": 1,
      "energy": 0.1,
      "energyType": 2
    },
    {
      "x": 11,
      "y": 1,
      "z": 5,
      "materialId": 1,
      "energy": 0.1,
      "energyType": 2
    },
    {
      "x": 12,
      "y": 1,
      "z": 5,
      "materialId": 1,
      "energy": 0.1,
      "energyType": 2
    },
    {
      "x": 13,
      "y": 1,
      "z": 5,
      "materialId": 1,
      "energy": 0.1,
      "energyType": 2
    },
    {
      "x": 4,
      "y": 1,
      "z": 6,
      "materialId": 1,
      "energy": 0.1,
      "energyType": 2
    },
    {
      "x": 5,
      "y": 1,
      "z": 6,
      "materialId": 1,
      "energy": 0.1,
      "energyType": 2
    },
    {
      "x": 6,
      "y": 1,
      "z": 6,
      "materialId": 1,
      "energy": 0.1,
      "energyType": 2
    },
    {
      "x": 7,
      "y": 1,
      "z": 6,
      "materialId": 1,
      "energy": 0.1,
      "energyType": 2
    },
    {
      "x": 10,
      "y": 1,
      "z": 6,
      "materialId": 1,
      "energy": 0.1,
      "energyType": 2
    },
    {
      "x": 11,
      "y": 1,
      "z": 6,
      "materialId": 1,
      "energy": 0.1,
      "energyType": 2
    },
    {
      "x": 12,
      "y": 1,
      "z": 6,
      "materialId": 1,
      "energy": 0.1,
      "energyType": 2
    },
    {
      "x": 13,
      "y": 1,
      "z": 6,
      "materialId": 1,
      "energy": 0.1,
      "energyType": 2
    },
    {
      "x": 4,
      "y": 1,
      "z": 7,
      "materialId": 1,
      "energy": 0.1,
      "energyType": 2
    },
    {
      "x": 5,
      "y": 1,
      "z": 7,
      "materialId": 1,
      "energy": 0.1,
      "energyType": 2
    },
    {
      "x": 6,
      "y": 1,
      "z": 7,
      "materialId": 1,
      "energy": 0.1,
      "energyType": 2
    },
    {
      "x": 7,
      "y": 1,
      "z": 7,
      "materialId": 1,
      "energy": 0.1,
      "energyType": 2
    },
    {
      "x": 10,
      "y": 1,
      "z": 7,
      "materialId": 1,
      "energy": 0.1,
      "energyType": 2
    },
    {
      "x": 11,
      "y": 1,
      "z": 7,
      "materialId": 1,
      "energy": 0.1,
      "energyType": 2
    },
    {
      "x": 12,
      "y": 1,
      "z": 7,
      "materialId": 1,
      "energy": 0.1,
      "energyType": 2
    },
    {
      "x": 13,
      "y": 1,
      "z": 7,
      "materialId": 1,
      "energy": 0.1,
      "energyType": 2
    },
    {
      "x": 5,
      "y": 2,
      "z": 3,
      "materialId": 1,
      "energy": 0.1,
      "energyType": 2
    },
    {
      "x": 6,
      "y": 2,
      "z": 3,
      "materialId": 1,
      "energy": 0.1,
      "energyType": 2
    },
    {
      "x": 7,
      "y": 2,
      "z": 3,
      "materialId": 1,
      "energy": 0.1,
      "energyType": 2
    },
    {
      "x": 10,
      "y": 2,
      "z": 3,
      "materialId": 1,
      "energy": 0.1,
      "energyType": 2
    },
    {
      "x": 11,
      "y": 2,
      "z": 3,
      "materialId": 1,
      "energy": 0.1,
      "energyType": 2
    },
    {
      "x": 12,
      "y": 2,
      "z": 3,
      "materialId": 1,
      "energy": 0.1,
      "energyType": 2
    },
    {
      "x": 5,
      "y": 2,
      "z": 4,
      "materialId": 1,
      "energy": 0.1,
      "energyType": 2
    },
    {
      "x": 6,
      "y": 2,
      "z": 4,
      "materialId": 1,
      "energy": 0.1,
      "energyType": 2
    },
    {
      "x": 7,
      "y": 2,
      "z": 4,
      "materialId": 1,
      "energy": 0.1,
      "energyType": 2
    },
    {
      "x": 10,
      "y": 2,
      "z": 4,
      "materialId": 1,
      "energy": 0.1,
      "energyType": 2
    },
    {
      "x": 11,
      "y": 2,
      "z": 4,
      "materialId": 1,
      "energy": 0.1,
      "energyType": 2
    },
    {
      "x": 12,
      "y": 2,
      "z": 4,
      "materialId": 1,
      "energy": 0.1,
      "energyType": 2
    },
    {
      "x": 5,
      "y": 2,
      "z": 5,
      "materialId": 1,
      "energy": 0.1,
      "energyType": 2
    },
    {
      "x": 6,
      "y": 2,
      "z": 5,
      "materialId": 1,
      "energy": 0.1,
      "energyType": 2
    },
    {
      "x": 7,
      "y": 2,
      "z": 5,
      "materialId": 1,
      "energy": 0.1,
      "energyType": 2
    },
    {
      "x": 10,
      "y": 2,
      "z": 5,
      "materialId": 1,
      "energy": 0.1,
      "energyType": 2
    },
    {
      "x": 11,
      "y": 2,
      "z": 5,
      "materialId": 1,
      "energy": 0.1,
      "energyType": 2
    },
    {
      "x": 12,
      "y": 2,
      "z": 5,
      "materialId": 1,
      "energy": 0.1,
      "energyType": 2
    },
    {
      "x": 5,
      "y": 3,
      "z": 3,
      "materialId": 1,
      "energy": 0.1,
      "energyType": 2
    },
    {
      "x": 6,
      "y": 3,
      "z": 3,
      "materialId": 1,
      "energy": 0.1,
      "energyType": 2
    },
    {
      "x": 7,
      "y": 3,
      "z": 3,
      "materialId": 1,
      "energy": 0.1,
      "energyType": 2
    },
    {
      "x": 10,
      "y": 3,
      "z": 3,
      "materialId": 1,
      "energy": 0.1,
      "energyType": 2
    },
    {
      "x": 11,
      "y": 3,
      "z": 3,
      "materialId": 1,
      "energy": 0.1,
      "energyType": 2
    },
    {
      "x": 12,
      "y": 3,
      "z": 3,
      "materialId": 1,
      "energy": 0.1,
      "energyType": 2
    },
    {
      "x": 5,
      "y": 3,
      "z": 4,
      "materialId": 1,
      "energy": 0.1,
      "energyType": 2
    },
    {
      "x": 6,
      "y": 3,
      "z": 4,
      "materialId": 1,
      "energy": 0.1,
      "energyType": 2
    },
    {
      "x": 7,
      "y": 3,
      "z": 4,
      "materialId": 1,
      "energy": 0.1,
      "energyType": 2
    },
    {
      "x": 10,
      "y": 3,
      "z": 4,
      "materialId": 1,
      "energy": 0.1,
      "energyType": 2
    },
    {
      "x": 11,
      "y": 3,
      "z": 4,
      "materialId": 1,
      "energy": 0.1,
      "energyType": 2
    },
    {
      "x": 12,
      "y": 3,
      "z": 4,
      "materialId": 1,
      "energy": 0.1,
      "energyType": 2
    },
    {
      "x": 5,
      "y": 3,
      "z": 5,
      "materialId": 1,
      "energy": 0.1,
      "energyType": 2
    },
    {
      "x": 6,
      "y": 3,
      "z": 5,
      "materialId": 1,
      "energy": 0.1,
      "energyType": 2
    },
    {
      "x": 7,
      "y": 3,
      "z": 5,
      "materialId": 1,
      "energy": 0.1,
      "energyType": 2
    },
    {
      "x": 10,
      "y": 3,
      "z": 5,
      "materialId": 1,
      "energy": 0.1,
      "energyType": 2
    },
    {
      "x": 11,
      "y": 3,
      "z": 5,
      "materialId": 1,
      "energy": 0.1,
      "energyType": 2
    },
    {
      "x": 12,
      "y": 3,
      "z": 5,
      "materialId": 1,
      "energy": 0.1,
      "energyType": 2
    },
    {
      "x": 5,
      "y": 4,
      "z": 3,
      "materialId": 2,
      "energy": 0.2,
      "energyType": 2
    },
    {
      "x": 6,
      "y": 4,
      "z": 3,
      "materialId": 2,
      "energy": 0.2,
      "energyType": 2
    },
    {
      "x": 7,
      "y": 4,
      "z": 3,
      "materialId": 2,
      "energy": 0.2,
      "energyType": 2
    },
    {
      "x": 8,
      "y": 4,
      "z": 3,
      "materialId": 2,
      "energy": 0.2,
      "energyType": 2
    },
    {
      "x": 9,
      "y": 4,
      "z": 3,
      "materialId": 2,
      "energy": 0.2,
      "energyType": 2
    },
    {
      "x": 10,
      "y": 4,
      "z": 3,
      "materialId": 2,
      "energy": 0.2,
      "energyType": 2
    },
    {
      "x": 11,
      "y": 4,
      "z": 3,
      "materialId": 2,
      "energy": 0.2,
      "energyType": 2
    },
    {
      "x": 12,
      "y": 4,
      "z": 3,
      "materialId": 2,
      "energy": 0.2,
      "energyType": 2
    },
    {
      "x": 5,
      "y": 4,
      "z": 4,
      "materialId": 2,
      "energy": 0.2,
      "energyType": 2
    },
    {
      "x": 6,
      "y": 4,
      "z": 4,
      "materialId": 2,
      "energy": 0.2,
      "energyType": 2
    },
    {
      "x": 7,
      "y": 4,
      "z": 4,
      "materialId": 2,
      "energy": 0.2,
      "energyType": 2
    },
    {
      "x": 8,
      "y": 4,
      "z": 4,
      "materialId": 2,
      "energy": 0.2,
      "energyType": 2
    },
    {
      "x": 9,
      "y": 4,
      "z": 4,
      "materialId": 2,
      "energy": 0.2,
      "energyType": 2
    },
    {
      "x": 10,
      "y": 4,
      "z": 4,
      "materialId": 2,
      "energy": 0.2,
      "energyType": 2
    },
    {
      "x": 11,
      "y": 4,
      "z": 4,
      "materialId": 2,
      "energy": 0.2,
      "energyType": 2
    },
    {
      "x": 12,
      "y": 4,
      "z": 4,
      "materialId": 2,
      "energy": 0.2,
      "energyType": 2
    },
    {
      "x": 5,
      "y": 4,
      "z": 5,
      "materialId": 2,
      "energy": 0.2,
      "energyType": 2
    },
    {
      "x": 6,
      "y": 4,
      "z": 5,
      "materialId": 2,
      "energy": 0.2,
      "energyType": 2
    },
    {
      "x": 7,
      "y": 4,
      "z": 5,
      "materialId": 2,
      "energy": 0.2,
      "energyType": 2
    },
    {
      "x": 8,
      "y": 4,
      "z": 5,
      "materialId": 2,
      "energy": 0.2,
      "energyType": 2
    },
    {
      "x": 9,
      "y": 4,
      "z": 5,
      "materialId": 2,
      "energy": 0.2,
      "energyType": 2
    },
    {
      "x": 10,
      "y": 4,
      "z": 5,
      "materialId": 2,
      "energy": 0.2,
      "energyType": 2
    },
    {
      "x": 11,
      "y": 4,
      "z": 5,
      "materialId": 2,
      "energy": 0.2,
      "energyType": 2
    },
    {
      "x": 12,
      "y": 4,
      "z": 5,
      "materialId": 2,
      "energy": 0.2,
      "energyType": 2
    },
    {
      "x": 5,
      "y": 4,
      "z": 6,
      "materialId": 2,
      "energy": 0.2,
      "energyType": 2
    },
    {
      "x": 6,
      "y": 4,
      "z": 6,
      "materialId": 2,
      "energy": 0.2,
      "energyType": 2
    },
    {
      "x": 7,
      "y": 4,
      "z": 6,
      "materialId": 2,
      "energy": 0.2,
      "energyType": 2
    },
    {
      "x": 8,
      "y": 4,
      "z": 6,
      "materialId": 2,
      "energy": 0.2,
      "energyType": 2
    },
    {
      "x": 9,
      "y": 4,
      "z": 6,
      "materialId": 2,
      "energy": 0.2,
      "energyType": 2
    },
    {
      "x": 10,
      "y": 4,
      "z": 6,
      "materialId": 2,
      "energy": 0.2,
      "energyType": 2
    },
    {
      "x": 11,
      "y": 4,
      "z": 6,
      "materialId": 2,
      "energy": 0.2,
      "energyType": 2
    },
    {
      "x": 12,
      "y": 4,
      "z": 6,
      "materialId": 2,
      "energy": 0.2,
      "energyType": 2
    },
    {
      "x": 5,
      "y": 5,
      "z": 3,
      "materialId": 2,
      "energy": 0.2,
      "energyType": 2
    },
    {
      "x": 6,
      "y": 5,
      "z": 3,
      "materialId": 2,
      "energy": 0.2,
      "energyType": 2
    },
    {
      "x": 7,
      "y": 5,
      "z": 3,
      "materialId": 2,
      "energy": 0.2,
      "energyType": 2
    },
    {
      "x": 8,
      "y": 5,
      "z": 3,
      "materialId": 2,
      "energy": 0.2,
      "energyType": 2
    },
    {
      "x": 9,
      "y": 5,
      "z": 3,
      "materialId": 2,
      "energy": 0.2,
      "energyType": 2
    },
    {
      "x": 10,
      "y": 5,
      "z": 3,
      "materialId": 2,
      "energy": 0.2,
      "energyType": 2
    },
    {
      "x": 11,
      "y": 5,
      "z": 3,
      "materialId": 2,
      "energy": 0.2,
      "energyType": 2
    },
    {
      "x": 12,
      "y": 5,
      "z": 3,
      "materialId": 2,
      "energy": 0.2,
      "energyType": 2
    },
    {
      "x": 5,
      "y": 5,
      "z": 4,
      "materialId": 2,
      "energy": 0.2,
      "energyType": 2
    },
    {
      "x": 6,
      "y": 5,
      "z": 4,
      "materialId": 2,
      "energy": 0.2,
      "energyType": 2
    },
    {
      "x": 7,
      "y": 5,
      "z": 4,
      "materialId": 2,
      "energy": 0.2,
      "energyType": 2
    },
    {
      "x": 8,
      "y": 5,
      "z": 4,
      "materialId": 2,
      "energy": 0.2,
      "energyType": 2
    },
    {
      "x": 9,
      "y": 5,
      "z": 4,
      "materialId": 2,
      "energy": 0.2,
      "energyType": 2
    },
    {
      "x": 10,
      "y": 5,
      "z": 4,
      "materialId": 2,
      "energy": 0.2,
      "energyType": 2
    },
    {
      "x": 11,
      "y": 5,
      "z": 4,
      "materialId": 2,
      "energy": 0.2,
      "energyType": 2
    },
    {
      "x": 12,
      "y": 5,
      "z": 4,
      "materialId": 2,
      "energy": 0.2,
      "energyType": 2
    },
    {
      "x": 5,
      "y": 5,
      "z": 5,
      "materialId": 2,
      "energy": 0.2,
      "energyType": 2
    },
    {
      "x": 6,
      "y": 5,
      "z": 5,
      "materialId": 2,
      "energy": 0.2,
      "energyType": 2
    },
    {
      "x": 7,
      "y": 5,
      "z": 5,
      "materialId": 2,
      "energy": 0.2,
      "energyType": 2
    },
    {
      "x": 8,
      "y": 5,
      "z": 5,
      "materialId": 2,
      "energy": 0.2,
      "energyType": 2
    },
    {
      "x": 9,
      "y": 5,
      "z": 5,
      "materialId": 2,
      "energy": 0.2,
      "energyType": 2
    },
    {
      "x": 10,
      "y": 5,
      "z": 5,
      "materialId": 2,
      "energy": 0.2,
      "energyType": 2
    },
    {
      "x": 11,
      "y": 5,
      "z": 5,
      "materialId": 2,
      "energy": 0.2,
      "energyType": 2
    },
    {
      "x": 12,
      "y": 5,
      "z": 5,
      "materialId": 2,
      "energy": 0.2,
      "energyType": 2
    },
    {
      "x": 5,
      "y": 5,
      "z": 6,
      "materialId": 2,
      "energy": 0.2,
      "energyType": 2
    },
    {
      "x": 6,
      "y": 5,
      "z": 6,
      "materialId": 2,
      "energy": 0.2,
      "energyType": 2
    },
    {
      "x": 7,
      "y": 5,
      "z": 6,
      "materialId": 2,
      "energy": 0.2,
      "energyType": 2
    },
    {
      "x": 8,
      "y": 5,
      "z": 6,
      "materialId": 2,
      "energy": 0.2,
      "energyType": 2
    },
    {
      "x": 9,
      "y": 5,
      "z": 6,
      "materialId": 2,
      "energy": 0.2,
      "energyType": 2
    },
    {
      "x": 10,
      "y": 5,
      "z": 6,
      "materialId": 2,
      "energy": 0.2,
      "energyType": 2
    },
    {
      "x": 11,
      "y": 5,
      "z": 6,
      "materialId": 2,
      "energy": 0.2,
      "energyType": 2
    },
    {
      "x": 12,
      "y": 5,
      "z": 6,
      "materialId": 2,
      "energy": 0.2,
      "energyType": 2
    },
    {
      "x": 5,
      "y": 6,
      "z": 3,
      "materialId": 2,
      "energy": 0.2,
      "energyType": 2
    },
    {
      "x": 6,
      "y": 6,
      "z": 3,
      "materialId": 2,
      "energy": 0.2,
      "energyType": 2
    },
    {
      "x": 7,
      "y": 6,
      "z": 3,
      "materialId": 2,
      "energy": 0.2,
      "energyType": 2
    },
    {
      "x": 8,
      "y": 6,
      "z": 3,
      "materialId": 2,
      "energy": 0.2,
      "energyType": 2
    },
    {
      "x": 9,
      "y": 6,
      "z": 3,
      "materialId": 2,
      "energy": 0.2,
      "energyType": 2
    },
    {
      "x": 10,
      "y": 6,
      "z": 3,
      "materialId": 2,
      "energy": 0.2,
      "energyType": 2
    },
    {
      "x": 11,
      "y": 6,
      "z": 3,
      "materialId": 2,
      "energy": 0.2,
      "energyType": 2
    },
    {
      "x": 12,
      "y": 6,
      "z": 3,
      "materialId": 2,
      "energy": 0.2,
      "energyType": 2
    },
    {
      "x": 5,
      "y": 6,
      "z": 4,
      "materialId": 2,
      "energy": 0.2,
      "energyType": 2
    },
    {
      "x": 6,
      "y": 6,
      "z": 4,
      "materialId": 2,
      "energy": 0.2,
      "energyType": 2
    },
    {
      "x": 7,
      "y": 6,
      "z": 4,
      "materialId": 2,
      "energy": 0.2,
      "energyType": 2
    },
    {
      "x": 8,
      "y": 6,
      "z": 4,
      "materialId": 2,
      "energy": 0.2,
      "energyType": 2
    },
    {
      "x": 9,
      "y": 6,
      "z": 4,
      "materialId": 2,
      "energy": 0.2,
      "energyType": 2
    },
    {
      "x": 10,
      "y": 6,
      "z": 4,
      "materialId": 2,
      "energy": 0.2,
      "energyType": 2
    },
    {
      "x": 11,
      "y": 6,
      "z": 4,
      "materialId": 2,
      "energy": 0.2,
      "energyType": 2
    },
    {
      "x": 12,
      "y": 6,
      "z": 4,
      "materialId": 2,
      "energy": 0.2,
      "energyType": 2
    },
    {
      "x": 5,
      "y": 6,
      "z": 5,
      "materialId": 2,
      "energy": 0.2,
      "energyType": 2
    },
    {
      "x": 6,
      "y": 6,
      "z": 5,
      "materialId": 2,
      "energy": 0.2,
      "energyType": 2
    },
    {
      "x": 7,
      "y": 6,
      "z": 5,
      "materialId": 2,
      "energy": 0.2,
      "energyType": 2
    },
    {
      "x": 8,
      "y": 6,
      "z": 5,
      "materialId": 2,
      "energy": 0.2,
      "energyType": 2
    },
    {
      "x": 9,
      "y": 6,
      "z": 5,
      "materialId": 2,
      "energy": 0.2,
      "energyType": 2
    },
    {
      "x": 10,
      "y": 6,
      "z": 5,
      "materialId": 2,
      "energy": 0.2,
      "energyType": 2
    },
    {
      "x": 11,
      "y": 6,
      "z": 5,
      "materialId": 2,
      "energy": 0.2,
      "energyType": 2
    },
    {
      "x": 12,
      "y": 6,
      "z": 5,
      "materialId": 2,
      "energy": 0.2,
      "energyType": 2
    },
    {
      "x": 5,
      "y": 6,
      "z": 6,
      "materialId": 2,
      "energy": 0.2,
      "energyType": 2
    },
    {
      "x": 6,
      "y": 6,
      "z": 6,
      "materialId": 2,
      "energy": 0.2,
      "energyType": 2
    },
    {
      "x": 7,
      "y": 6,
      "z": 6,
      "materialId": 2,
      "energy": 0.2,
      "energyType": 2
    },
    {
      "x": 8,
      "y": 6,
      "z": 6,
      "materialId": 2,
      "energy": 0.2,
      "energyType": 2
    },
    {
      "x": 9,
      "y": 6,
      "z": 6,
      "materialId": 2,
      "energy": 0.2,
      "energyType": 2
    },
    {
      "x": 10,
      "y": 6,
      "z": 6,
      "materialId": 2,
      "energy": 0.2,
      "energyType": 2
    },
    {
      "x": 11,
      "y": 6,
      "z": 6,
      "materialId": 2,
      "energy": 0.2,
      "energyType": 2
    },
    {
      "x": 12,
      "y": 6,
      "z": 6,
      "materialId": 2,
      "energy": 0.2,
      "energyType": 2
    },
    {
      "x": 8,
      "y": 7,
      "z": 2,
      "materialId": 4,
      "energy": 0.7,
      "energyType": 0
    },
    {
      "x": 9,
      "y": 7,
      "z": 2,
      "materialId": 4,
      "energy": 0.7,
      "energyType": 0
    },
    {
      "x": 5,
      "y": 7,
      "z": 3,
      "materialId": 2,
      "energy": 0.2,
      "energyType": 2
    },
    {
      "x": 6,
      "y": 7,
      "z": 3,
      "materialId": 2,
      "energy": 0.2,
      "energyType": 2
    },
    {
      "x": 7,
      "y": 7,
      "z": 3,
      "materialId": 2,
      "energy": 0.2,
      "energyType": 2
    },
    {
      "x": 8,
      "y": 7,
      "z": 3,
      "materialId": 2,
      "energy": 0.2,
      "energyType": 2
    },
    {
      "x": 9,
      "y": 7,
      "z": 3,
      "materialId": 2,
      "energy": 0.2,
      "energyType": 2
    },
    {
      "x": 10,
      "y": 7,
      "z": 3,
      "materialId": 2,
      "energy": 0.2,
      "energyType": 2
    },
    {
      "x": 11,
      "y": 7,
      "z": 3,
      "materialId": 2,
      "energy": 0.2,
      "energyType": 2
    },
    {
      "x": 12,
      "y": 7,
      "z": 3,
      "materialId": 2,
      "energy": 0.2,
      "energyType": 2
    },
    {
      "x": 5,
      "y": 7,
      "z": 4,
      "materialId": 2,
      "energy": 0.2,
      "energyType": 2
    },
    {
      "x": 6,
      "y": 7,
      "z": 4,
      "materialId": 2,
      "energy": 0.2,
      "energyType": 2
    },
    {
      "x": 7,
      "y": 7,
      "z": 4,
      "materialId": 2,
      "energy": 0.2,
      "energyType": 2
    },
    {
      "x": 8,
      "y": 7,
      "z": 4,
      "materialId": 2,
      "energy": 0.2,
      "energyType": 2
    },
    {
      "x": 9,
      "y": 7,
      "z": 4,
      "materialId": 2,
      "energy": 0.2,
      "energyType": 2
    },
    {
      "x": 10,
      "y": 7,
      "z": 4,
      "materialId": 2,
      "energy": 0.2,
      "energyType": 2
    },
    {
      "x": 11,
      "y": 7,
      "z": 4,
      "materialId": 2,
      "energy": 0.2,
      "energyType": 2
    },
    {
      "x": 12,
      "y": 7,
      "z": 4,
      "materialId": 2,
      "energy": 0.2,
      "energyType": 2
    },
    {
      "x": 5,
      "y": 7,
      "z": 5,
      "materialId": 2,
      "energy": 0.2,
      "energyType": 2
    },
    {
      "x": 6,
      "y": 7,
      "z": 5,
      "materialId": 2,
      "energy": 0.2,
      "energyType": 2
    },
    {
      "x": 7,
      "y": 7,
      "z": 5,
      "materialId": 2,
      "energy": 0.2,
      "energyType": 2
    },
    {
      "x": 8,
      "y": 7,
      "z": 5,
      "materialId": 2,
      "energy": 0.2,
      "energyType": 2
    },
    {
      "x": 9,
      "y": 7,
      "z": 5,
      "materialId": 2,
      "energy": 0.2,
      "energyType": 2
    },
    {
      "x": 10,
      "y": 7,
      "z": 5,
      "materialId": 2,
      "energy": 0.2,
      "energyType": 2
    },
    {
      "x": 11,
      "y": 7,
      "z": 5,
      "materialId": 2,
      "energy": 0.2,
      "energyType": 2
    },
    {
      "x": 12,
      "y": 7,
      "z": 5,
      "materialId": 2,
      "energy": 0.2,
      "energyType": 2
    },
    {
      "x": 5,
      "y": 7,
      "z": 6,
      "materialId": 2,
      "energy": 0.2,
      "energyType": 2
    },
    {
      "x": 6,
      "y": 7,
      "z": 6,
      "materialId": 2,
      "energy": 0.2,
      "energyType": 2
    },
    {
      "x": 7,
      "y": 7,
      "z": 6,
      "materialId": 2,
      "energy": 0.2,
      "energyType": 2
    },
    {
      "x": 8,
      "y": 7,
      "z": 6,
      "materialId": 2,
      "energy": 0.2,
      "energyType": 2
    },
    {
      "x": 9,
      "y": 7,
      "z": 6,
      "materialId": 2,
      "energy": 0.2,
      "energyType": 2
    },
    {
      "x": 10,
      "y": 7,
      "z": 6,
      "materialId": 2,
      "energy": 0.2,
      "energyType": 2
    },
    {
      "x": 11,
      "y": 7,
      "z": 6,
      "materialId": 2,
      "energy": 0.2,
      "energyType": 2
    },
    {
      "x": 12,
      "y": 7,
      "z": 6,
      "materialId": 2,
      "energy": 0.2,
      "energyType": 2
    },
    {
      "x": 5,
      "y": 8,
      "z": 3,
      "materialId": 2,
      "energy": 0.2,
      "energyType": 2
    },
    {
      "x": 6,
      "y": 8,
      "z": 3,
      "materialId": 2,
      "energy": 0.2,
      "energyType": 2
    },
    {
      "x": 7,
      "y": 8,
      "z": 3,
      "materialId": 2,
      "energy": 0.2,
      "energyType": 2
    },
    {
      "x": 8,
      "y": 8,
      "z": 3,
      "materialId": 2,
      "energy": 0.2,
      "energyType": 2
    },
    {
      "x": 9,
      "y": 8,
      "z": 3,
      "materialId": 2,
      "energy": 0.2,
      "energyType": 2
    },
    {
      "x": 10,
      "y": 8,
      "z": 3,
      "materialId": 2,
      "energy": 0.2,
      "energyType": 2
    },
    {
      "x": 11,
      "y": 8,
      "z": 3,
      "materialId": 2,
      "energy": 0.2,
      "energyType": 2
    },
    {
      "x": 12,
      "y": 8,
      "z": 3,
      "materialId": 2,
      "energy": 0.2,
      "energyType": 2
    },
    {
      "x": 1,
      "y": 8,
      "z": 4,
      "materialId": 5,
      "energy": 0.35,
      "energyType": 0
    },
    {
      "x": 2,
      "y": 8,
      "z": 4,
      "materialId": 5,
      "energy": 0.35,
      "energyType": 0
    },
    {
      "x": 3,
      "y": 8,
      "z": 4,
      "materialId": 5,
      "energy": 0.35,
      "energyType": 0
    },
    {
      "x": 5,
      "y": 8,
      "z": 4,
      "materialId": 2,
      "energy": 0.2,
      "energyType": 2
    },
    {
      "x": 6,
      "y": 8,
      "z": 4,
      "materialId": 2,
      "energy": 0.2,
      "energyType": 2
    },
    {
      "x": 7,
      "y": 8,
      "z": 4,
      "materialId": 2,
      "energy": 0.2,
      "energyType": 2
    },
    {
      "x": 8,
      "y": 8,
      "z": 4,
      "materialId": 2,
      "energy": 0.2,
      "energyType": 2
    },
    {
      "x": 9,
      "y": 8,
      "z": 4,
      "materialId": 2,
      "energy": 0.2,
      "energyType": 2
    },
    {
      "x": 10,
      "y": 8,
      "z": 4,
      "materialId": 2,
      "energy": 0.2,
      "energyType": 2
    },
    {
      "x": 11,
      "y": 8,
      "z": 4,
      "materialId": 2,
      "energy": 0.2,
      "energyType": 2
    },
    {
      "x": 12,
      "y": 8,
      "z": 4,
      "materialId": 2,
      "energy": 0.2,
      "energyType": 2
    },
    {
      "x": 1,
      "y": 8,
      "z": 5,
      "materialId": 5,
      "energy": 0.35,
      "energyType": 0
    },
    {
      "x": 2,
      "y": 8,
      "z": 5,
      "materialId": 5,
      "energy": 0.35,
      "energyType": 0
    },
    {
      "x": 3,
      "y": 8,
      "z": 5,
      "materialId": 5,
      "energy": 0.35,
      "energyType": 0
    },
    {
      "x": 5,
      "y": 8,
      "z": 5,
      "materialId": 2,
      "energy": 0.2,
      "energyType": 2
    },
    {
      "x": 6,
      "y": 8,
      "z": 5,
      "materialId": 2,
      "energy": 0.2,
      "energyType": 2
    },
    {
      "x": 7,
      "y": 8,
      "z": 5,
      "materialId": 2,
      "energy": 0.2,
      "energyType": 2
    },
    {
      "x": 8,
      "y": 8,
      "z": 5,
      "materialId": 2,
      "energy": 0.2,
      "energyType": 2
    },
    {
      "x": 9,
      "y": 8,
      "z": 5,
      "materialId": 2,
      "energy": 0.2,
      "energyType": 2
    },
    {
      "x": 10,
      "y": 8,
      "z": 5,
      "materialId": 2,
      "energy": 0.2,
      "energyType": 2
    },
    {
      "x": 11,
      "y": 8,
      "z": 5,
      "materialId": 2,
      "energy": 0.2,
      "energyType": 2
    },
    {
      "x": 12,
      "y": 8,
      "z": 5,
      "materialId": 2,
      "energy": 0.2,
      "energyType": 2
    },
    {
      "x": 14,
      "y": 8,
      "z": 5,
      "materialId": 5,
      "energy": 0.35,
      "energyType": 0
    },
    {
      "x": 15,
      "y": 8,
      "z": 5,
      "materialId": 5,
      "energy": 0.35,
      "energyType": 0
    },
    {
      "x": 16,
      "y": 8,
      "z": 5,
      "materialId": 5,
      "energy": 0.35,
      "energyType": 0
    },
    {
      "x": 5,
      "y": 8,
      "z": 6,
      "materialId": 2,
      "energy": 0.2,
      "energyType": 2
    },
    {
      "x": 6,
      "y": 8,
      "z": 6,
      "materialId": 2,
      "energy": 0.2,
      "energyType": 2
    },
    {
      "x": 7,
      "y": 8,
      "z": 6,
      "materialId": 2,
      "energy": 0.2,
      "energyType": 2
    },
    {
      "x": 8,
      "y": 8,
      "z": 6,
      "materialId": 2,
      "energy": 0.2,
      "energyType": 2
    },
    {
      "x": 9,
      "y": 8,
      "z": 6,
      "materialId": 2,
      "energy": 0.2,
      "energyType": 2
    },
    {
      "x": 10,
      "y": 8,
      "z": 6,
      "materialId": 2,
      "energy": 0.2,
      "energyType": 2
    },
    {
      "x": 11,
      "y": 8,
      "z": 6,
      "materialId": 2,
      "energy": 0.2,
      "energyType": 2
    },
    {
      "x": 12,
      "y": 8,
      "z": 6,
      "materialId": 2,
      "energy": 0.2,
      "energyType": 2
    },
    {
      "x": 14,
      "y": 8,
      "z": 6,
      "materialId": 5,
      "energy": 0.35,
      "energyType": 0
    },
    {
      "x": 15,
      "y": 8,
      "z": 6,
      "materialId": 5,
      "energy": 0.35,
      "energyType": 0
    },
    {
      "x": 16,
      "y": 8,
      "z": 6,
      "materialId": 5,
      "energy": 0.35,
      "energyType": 0
    },
    {
      "x": 5,
      "y": 8,
      "z": 7,
      "materialId": 1,
      "energy": 0.1,
      "energyType": 6
    },
    {
      "x": 6,
      "y": 8,
      "z": 7,
      "materialId": 1,
      "energy": 0.1,
      "energyType": 6
    },
    {
      "x": 7,
      "y": 8,
      "z": 7,
      "materialId": 1,
      "energy": 0.1,
      "energyType": 6
    },
    {
      "x": 8,
      "y": 8,
      "z": 7,
      "materialId": 1,
      "energy": 0.1,
      "energyType": 6
    },
    {
      "x": 9,
      "y": 8,
      "z": 7,
      "materialId": 1,
      "energy": 0.1,
      "energyType": 6
    },
    {
      "x": 10,
      "y": 8,
      "z": 7,
      "materialId": 1,
      "energy": 0.1,
      "energyType": 6
    },
    {
      "x": 11,
      "y": 8,
      "z": 7,
      "materialId": 1,
      "energy": 0.1,
      "energyType": 6
    },
    {
      "x": 12,
      "y": 8,
      "z": 7,
      "materialId": 1,
      "energy": 0.1,
      "energyType": 6
    },
    {
      "x": 5,
      "y": 8,
      "z": 8,
      "materialId": 1,
      "energy": 0.1,
      "energyType": 6
    },
    {
      "x": 6,
      "y": 8,
      "z": 8,
      "materialId": 1,
      "energy": 0.1,
      "energyType": 6
    },
    {
      "x": 7,
      "y": 8,
      "z": 8,
      "materialId": 1,
      "energy": 0.1,
      "energyType": 6
    },
    {
      "x": 8,
      "y": 8,
      "z": 8,
      "materialId": 1,
      "energy": 0.1,
      "energyType": 6
    },
    {
      "x": 9,
      "y": 8,
      "z": 8,
      "materialId": 1,
      "energy": 0.1,
      "energyType": 6
    },
    {
      "x": 10,
      "y": 8,
      "z": 8,
      "materialId": 1,
      "energy": 0.1,
      "energyType": 6
    },
    {
      "x": 11,
      "y": 8,
      "z": 8,
      "materialId": 1,
      "energy": 0.1,
      "energyType": 6
    },
    {
      "x": 12,
      "y": 8,
      "z": 8,
      "materialId": 1,
      "energy": 0.1,
      "energyType": 6
    },
    {
      "x": 5,
      "y": 9,
      "z": 3,
      "materialId": 2,
      "energy": 0.2,
      "energyType": 2
    },
    {
      "x": 6,
      "y": 9,
      "z": 3,
      "materialId": 2,
      "energy": 0.2,
      "energyType": 2
    },
    {
      "x": 7,
      "y": 9,
      "z": 3,
      "materialId": 2,
      "energy": 0.2,
      "energyType": 2
    },
    {
      "x": 8,
      "y": 9,
      "z": 3,
      "materialId": 2,
      "energy": 0.2,
      "energyType": 2
    },
    {
      "x": 9,
      "y": 9,
      "z": 3,
      "materialId": 2,
      "energy": 0.2,
      "energyType": 2
    },
    {
      "x": 10,
      "y": 9,
      "z": 3,
      "materialId": 2,
      "energy": 0.2,
      "energyType": 2
    },
    {
      "x": 11,
      "y": 9,
      "z": 3,
      "materialId": 2,
      "energy": 0.2,
      "energyType": 2
    },
    {
      "x": 12,
      "y": 9,
      "z": 3,
      "materialId": 2,
      "energy": 0.2,
      "energyType": 2
    },
    {
      "x": 1,
      "y": 9,
      "z": 4,
      "materialId": 5,
      "energy": 0.35,
      "energyType": 0
    },
    {
      "x": 2,
      "y": 9,
      "z": 4,
      "materialId": 5,
      "energy": 0.35,
      "energyType": 0
    },
    {
      "x": 3,
      "y": 9,
      "z": 4,
      "materialId": 5,
      "energy": 0.35,
      "energyType": 0
    },
    {
      "x": 5,
      "y": 9,
      "z": 4,
      "materialId": 2,
      "energy": 0.2,
      "energyType": 2
    },
    {
      "x": 6,
      "y": 9,
      "z": 4,
      "materialId": 2,
      "energy": 0.2,
      "energyType": 2
    },
    {
      "x": 7,
      "y": 9,
      "z": 4,
      "materialId": 2,
      "energy": 0.2,
      "energyType": 2
    },
    {
      "x": 8,
      "y": 9,
      "z": 4,
      "materialId": 2,
      "energy": 0.2,
      "energyType": 2
    },
    {
      "x": 9,
      "y": 9,
      "z": 4,
      "materialId": 2,
      "energy": 0.2,
      "energyType": 2
    },
    {
      "x": 10,
      "y": 9,
      "z": 4,
      "materialId": 2,
      "energy": 0.2,
      "energyType": 2
    },
    {
      "x": 11,
      "y": 9,
      "z": 4,
      "materialId": 2,
      "energy": 0.2,
      "energyType": 2
    },
    {
      "x": 12,
      "y": 9,
      "z": 4,
      "materialId": 2,
      "energy": 0.2,
      "energyType": 2
    },
    {
      "x": 1,
      "y": 9,
      "z": 5,
      "materialId": 5,
      "energy": 0.35,
      "energyType": 0
    },
    {
      "x": 2,
      "y": 9,
      "z": 5,
      "materialId": 5,
      "energy": 0.35,
      "energyType": 0
    },
    {
      "x": 3,
      "y": 9,
      "z": 5,
      "materialId": 5,
      "energy": 0.35,
      "energyType": 0
    },
    {
      "x": 5,
      "y": 9,
      "z": 5,
      "materialId": 2,
      "energy": 0.2,
      "energyType": 2
    },
    {
      "x": 6,
      "y": 9,
      "z": 5,
      "materialId": 2,
      "energy": 0.2,
      "energyType": 2
    },
    {
      "x": 7,
      "y": 9,
      "z": 5,
      "materialId": 2,
      "energy": 0.2,
      "energyType": 2
    },
    {
      "x": 8,
      "y": 9,
      "z": 5,
      "materialId": 2,
      "energy": 0.2,
      "energyType": 2
    },
    {
      "x": 9,
      "y": 9,
      "z": 5,
      "materialId": 2,
      "energy": 0.2,
      "energyType": 2
    },
    {
      "x": 10,
      "y": 9,
      "z": 5,
      "materialId": 2,
      "energy": 0.2,
      "energyType": 2
    },
    {
      "x": 11,
      "y": 9,
      "z": 5,
      "materialId": 2,
      "energy": 0.2,
      "energyType": 2
    },
    {
      "x": 12,
      "y": 9,
      "z": 5,
      "materialId": 2,
      "energy": 0.2,
      "energyType": 2
    },
    {
      "x": 14,
      "y": 9,
      "z": 5,
      "materialId": 5,
      "energy": 0.35,
      "energyType": 0
    },
    {
      "x": 15,
      "y": 9,
      "z": 5,
      "materialId": 5,
      "energy": 0.35,
      "energyType": 0
    },
    {
      "x": 16,
      "y": 9,
      "z": 5,
      "materialId": 5,
      "energy": 0.35,
      "energyType": 0
    },
    {
      "x": 5,
      "y": 9,
      "z": 6,
      "materialId": 2,
      "energy": 0.2,
      "energyType": 2
    },
    {
      "x": 6,
      "y": 9,
      "z": 6,
      "materialId": 2,
      "energy": 0.2,
      "energyType": 2
    },
    {
      "x": 7,
      "y": 9,
      "z": 6,
      "materialId": 2,
      "energy": 0.2,
      "energyType": 2
    },
    {
      "x": 8,
      "y": 9,
      "z": 6,
      "materialId": 2,
      "energy": 0.2,
      "energyType": 2
    },
    {
      "x": 9,
      "y": 9,
      "z": 6,
      "materialId": 2,
      "energy": 0.2,
      "energyType": 2
    },
    {
      "x": 10,
      "y": 9,
      "z": 6,
      "materialId": 2,
      "energy": 0.2,
      "energyType": 2
    },
    {
      "x": 11,
      "y": 9,
      "z": 6,
      "materialId": 2,
      "energy": 0.2,
      "energyType": 2
    },
    {
      "x": 12,
      "y": 9,
      "z": 6,
      "materialId": 2,
      "energy": 0.2,
      "energyType": 2
    },
    {
      "x": 14,
      "y": 9,
      "z": 6,
      "materialId": 5,
      "energy": 0.35,
      "energyType": 0
    },
    {
      "x": 15,
      "y": 9,
      "z": 6,
      "materialId": 5,
      "energy": 0.35,
      "energyType": 0
    },
    {
      "x": 16,
      "y": 9,
      "z": 6,
      "materialId": 5,
      "energy": 0.35,
      "energyType": 0
    },
    {
      "x": 5,
      "y": 9,
      "z": 7,
      "materialId": 1,
      "energy": 0.1,
      "energyType": 6
    },
    {
      "x": 6,
      "y": 9,
      "z": 7,
      "materialId": 1,
      "energy": 0.1,
      "energyType": 6
    },
    {
      "x": 7,
      "y": 9,
      "z": 7,
      "materialId": 1,
      "energy": 0.1,
      "energyType": 6
    },
    {
      "x": 8,
      "y": 9,
      "z": 7,
      "materialId": 1,
      "energy": 0.1,
      "energyType": 6
    },
    {
      "x": 9,
      "y": 9,
      "z": 7,
      "materialId": 1,
      "energy": 0.1,
      "energyType": 6
    },
    {
      "x": 10,
      "y": 9,
      "z": 7,
      "materialId": 1,
      "energy": 0.1,
      "energyType": 6
    },
    {
      "x": 11,
      "y": 9,
      "z": 7,
      "materialId": 1,
      "energy": 0.1,
      "energyType": 6
    },
    {
      "x": 12,
      "y": 9,
      "z": 7,
      "materialId": 1,
      "energy": 0.1,
      "energyType": 6
    },
    {
      "x": 5,
      "y": 9,
      "z": 8,
      "materialId": 1,
      "energy": 0.1,
      "energyType": 6
    },
    {
      "x": 6,
      "y": 9,
      "z": 8,
      "materialId": 1,
      "energy": 0.1,
      "energyType": 6
    },
    {
      "x": 7,
      "y": 9,
      "z": 8,
      "materialId": 1,
      "energy": 0.1,
      "energyType": 6
    },
    {
      "x": 8,
      "y": 9,
      "z": 8,
      "materialId": 1,
      "energy": 0.1,
      "energyType": 6
    },
    {
      "x": 9,
      "y": 9,
      "z": 8,
      "materialId": 1,
      "energy": 0.1,
      "energyType": 6
    },
    {
      "x": 10,
      "y": 9,
      "z": 8,
      "materialId": 1,
      "energy": 0.1,
      "energyType": 6
    },
    {
      "x": 11,
      "y": 9,
      "z": 8,
      "materialId": 1,
      "energy": 0.1,
      "energyType": 6
    },
    {
      "x": 12,
      "y": 9,
      "z": 8,
      "materialId": 1,
      "energy": 0.1,
      "energyType": 6
    },
    {
      "x": 5,
      "y": 10,
      "z": 2,
      "materialId": 3,
      "energy": 0.36,
      "energyType": 0
    },
    {
      "x": 6,
      "y": 10,
      "z": 2,
      "materialId": 3,
      "energy": 0.36,
      "energyType": 0
    },
    {
      "x": 7,
      "y": 10,
      "z": 2,
      "materialId": 3,
      "energy": 0.36,
      "energyType": 0
    },
    {
      "x": 8,
      "y": 10,
      "z": 2,
      "materialId": 4,
      "energy": 0.7,
      "energyType": 0
    },
    {
      "x": 9,
      "y": 10,
      "z": 2,
      "materialId": 4,
      "energy": 0.7,
      "energyType": 0
    },
    {
      "x": 10,
      "y": 10,
      "z": 2,
      "materialId": 3,
      "energy": 0.36,
      "energyType": 0
    },
    {
      "x": 11,
      "y": 10,
      "z": 2,
      "materialId": 3,
      "energy": 0.36,
      "energyType": 0
    },
    {
      "x": 12,
      "y": 10,
      "z": 2,
      "materialId": 3,
      "energy": 0.36,
      "energyType": 0
    },
    {
      "x": 2,
      "y": 10,
      "z": 3,
      "materialId": 3,
      "energy": 0.32,
      "energyType": 2
    },
    {
      "x": 3,
      "y": 10,
      "z": 3,
      "materialId": 3,
      "energy": 0.32,
      "energyType": 2
    },
    {
      "x": 4,
      "y": 10,
      "z": 3,
      "materialId": 3,
      "energy": 0.32,
      "energyType": 2
    },
    {
      "x": 5,
      "y": 10,
      "z": 3,
      "materialId": 3,
      "energy": 0.36,
      "energyType": 0
    },
    {
      "x": 6,
      "y": 10,
      "z": 3,
      "materialId": 3,
      "energy": 0.36,
      "energyType": 0
    },
    {
      "x": 7,
      "y": 10,
      "z": 3,
      "materialId": 3,
      "energy": 0.36,
      "energyType": 0
    },
    {
      "x": 8,
      "y": 10,
      "z": 3,
      "materialId": 3,
      "energy": 0.36,
      "energyType": 0
    },
    {
      "x": 9,
      "y": 10,
      "z": 3,
      "materialId": 3,
      "energy": 0.36,
      "energyType": 0
    },
    {
      "x": 10,
      "y": 10,
      "z": 3,
      "materialId": 3,
      "energy": 0.36,
      "energyType": 0
    },
    {
      "x": 11,
      "y": 10,
      "z": 3,
      "materialId": 3,
      "energy": 0.36,
      "energyType": 0
    },
    {
      "x": 12,
      "y": 10,
      "z": 3,
      "materialId": 3,
      "energy": 0.36,
      "energyType": 0
    },
    {
      "x": 1,
      "y": 10,
      "z": 4,
      "materialId": 5,
      "energy": 0.35,
      "energyType": 0
    },
    {
      "x": 2,
      "y": 10,
      "z": 4,
      "materialId": 5,
      "energy": 0.35,
      "energyType": 0
    },
    {
      "x": 3,
      "y": 10,
      "z": 4,
      "materialId": 5,
      "energy": 0.35,
      "energyType": 0
    },
    {
      "x": 4,
      "y": 10,
      "z": 4,
      "materialId": 3,
      "energy": 0.32,
      "energyType": 2
    },
    {
      "x": 5,
      "y": 10,
      "z": 4,
      "materialId": 2,
      "energy": 0.2,
      "energyType": 2
    },
    {
      "x": 6,
      "y": 10,
      "z": 4,
      "materialId": 2,
      "energy": 0.2,
      "energyType": 2
    },
    {
      "x": 7,
      "y": 10,
      "z": 4,
      "materialId": 2,
      "energy": 0.2,
      "energyType": 2
    },
    {
      "x": 8,
      "y": 10,
      "z": 4,
      "materialId": 2,
      "energy": 0.2,
      "energyType": 2
    },
    {
      "x": 9,
      "y": 10,
      "z": 4,
      "materialId": 2,
      "energy": 0.2,
      "energyType": 2
    },
    {
      "x": 10,
      "y": 10,
      "z": 4,
      "materialId": 2,
      "energy": 0.2,
      "energyType": 2
    },
    {
      "x": 11,
      "y": 10,
      "z": 4,
      "materialId": 2,
      "energy": 0.2,
      "energyType": 2
    },
    {
      "x": 12,
      "y": 10,
      "z": 4,
      "materialId": 2,
      "energy": 0.2,
      "energyType": 2
    },
    {
      "x": 13,
      "y": 10,
      "z": 4,
      "materialId": 3,
      "energy": 0.28,
      "energyType": 2
    },
    {
      "x": 14,
      "y": 10,
      "z": 4,
      "materialId": 3,
      "energy": 0.28,
      "energyType": 2
    },
    {
      "x": 15,
      "y": 10,
      "z": 4,
      "materialId": 3,
      "energy": 0.28,
      "energyType": 2
    },
    {
      "x": 1,
      "y": 10,
      "z": 5,
      "materialId": 5,
      "energy": 0.35,
      "energyType": 0
    },
    {
      "x": 2,
      "y": 10,
      "z": 5,
      "materialId": 5,
      "energy": 0.35,
      "energyType": 0
    },
    {
      "x": 3,
      "y": 10,
      "z": 5,
      "materialId": 5,
      "energy": 0.35,
      "energyType": 0
    },
    {
      "x": 4,
      "y": 10,
      "z": 5,
      "materialId": 3,
      "energy": 0.32,
      "energyType": 2
    },
    {
      "x": 5,
      "y": 10,
      "z": 5,
      "materialId": 2,
      "energy": 0.2,
      "energyType": 2
    },
    {
      "x": 6,
      "y": 10,
      "z": 5,
      "materialId": 2,
      "energy": 0.2,
      "energyType": 2
    },
    {
      "x": 7,
      "y": 10,
      "z": 5,
      "materialId": 2,
      "energy": 0.2,
      "energyType": 2
    },
    {
      "x": 8,
      "y": 10,
      "z": 5,
      "materialId": 2,
      "energy": 0.2,
      "energyType": 2
    },
    {
      "x": 9,
      "y": 10,
      "z": 5,
      "materialId": 2,
      "energy": 0.2,
      "energyType": 2
    },
    {
      "x": 10,
      "y": 10,
      "z": 5,
      "materialId": 2,
      "energy": 0.2,
      "energyType": 2
    },
    {
      "x": 11,
      "y": 10,
      "z": 5,
      "materialId": 2,
      "energy": 0.2,
      "energyType": 2
    },
    {
      "x": 12,
      "y": 10,
      "z": 5,
      "materialId": 2,
      "energy": 0.2,
      "energyType": 2
    },
    {
      "x": 13,
      "y": 10,
      "z": 5,
      "materialId": 3,
      "energy": 0.28,
      "energyType": 2
    },
    {
      "x": 14,
      "y": 10,
      "z": 5,
      "materialId": 5,
      "energy": 0.35,
      "energyType": 0
    },
    {
      "x": 15,
      "y": 10,
      "z": 5,
      "materialId": 5,
      "energy": 0.35,
      "energyType": 0
    },
    {
      "x": 16,
      "y": 10,
      "z": 5,
      "materialId": 5,
      "energy": 0.35,
      "energyType": 0
    },
    {
      "x": 5,
      "y": 10,
      "z": 6,
      "materialId": 2,
      "energy": 0.2,
      "energyType": 2
    },
    {
      "x": 6,
      "y": 10,
      "z": 6,
      "materialId": 2,
      "energy": 0.2,
      "energyType": 2
    },
    {
      "x": 7,
      "y": 10,
      "z": 6,
      "materialId": 2,
      "energy": 0.2,
      "energyType": 2
    },
    {
      "x": 8,
      "y": 10,
      "z": 6,
      "materialId": 2,
      "energy": 0.2,
      "energyType": 2
    },
    {
      "x": 9,
      "y": 10,
      "z": 6,
      "materialId": 2,
      "energy": 0.2,
      "energyType": 2
    },
    {
      "x": 10,
      "y": 10,
      "z": 6,
      "materialId": 2,
      "energy": 0.2,
      "energyType": 2
    },
    {
      "x": 11,
      "y": 10,
      "z": 6,
      "materialId": 2,
      "energy": 0.2,
      "energyType": 2
    },
    {
      "x": 12,
      "y": 10,
      "z": 6,
      "materialId": 2,
      "energy": 0.2,
      "energyType": 2
    },
    {
      "x": 13,
      "y": 10,
      "z": 6,
      "materialId": 3,
      "energy": 0.28,
      "energyType": 2
    },
    {
      "x": 14,
      "y": 10,
      "z": 6,
      "materialId": 5,
      "energy": 0.35,
      "energyType": 0
    },
    {
      "x": 15,
      "y": 10,
      "z": 6,
      "materialId": 5,
      "energy": 0.35,
      "energyType": 0
    },
    {
      "x": 16,
      "y": 10,
      "z": 6,
      "materialId": 5,
      "energy": 0.35,
      "energyType": 0
    },
    {
      "x": 5,
      "y": 10,
      "z": 7,
      "materialId": 1,
      "energy": 0.1,
      "energyType": 6
    },
    {
      "x": 6,
      "y": 10,
      "z": 7,
      "materialId": 1,
      "energy": 0.1,
      "energyType": 6
    },
    {
      "x": 7,
      "y": 10,
      "z": 7,
      "materialId": 1,
      "energy": 0.1,
      "energyType": 6
    },
    {
      "x": 8,
      "y": 10,
      "z": 7,
      "materialId": 1,
      "energy": 0.1,
      "energyType": 6
    },
    {
      "x": 9,
      "y": 10,
      "z": 7,
      "materialId": 1,
      "energy": 0.1,
      "energyType": 6
    },
    {
      "x": 10,
      "y": 10,
      "z": 7,
      "materialId": 1,
      "energy": 0.1,
      "energyType": 6
    },
    {
      "x": 11,
      "y": 10,
      "z": 7,
      "materialId": 1,
      "energy": 0.1,
      "energyType": 6
    },
    {
      "x": 12,
      "y": 10,
      "z": 7,
      "materialId": 1,
      "energy": 0.1,
      "energyType": 6
    },
    {
      "x": 5,
      "y": 10,
      "z": 8,
      "materialId": 1,
      "energy": 0.1,
      "energyType": 6
    },
    {
      "x": 6,
      "y": 10,
      "z": 8,
      "materialId": 1,
      "energy": 0.1,
      "energyType": 6
    },
    {
      "x": 7,
      "y": 10,
      "z": 8,
      "materialId": 1,
      "energy": 0.1,
      "energyType": 6
    },
    {
      "x": 8,
      "y": 10,
      "z": 8,
      "materialId": 1,
      "energy": 0.1,
      "energyType": 6
    },
    {
      "x": 9,
      "y": 10,
      "z": 8,
      "materialId": 1,
      "energy": 0.1,
      "energyType": 6
    },
    {
      "x": 10,
      "y": 10,
      "z": 8,
      "materialId": 1,
      "energy": 0.1,
      "energyType": 6
    },
    {
      "x": 11,
      "y": 10,
      "z": 8,
      "materialId": 1,
      "energy": 0.1,
      "energyType": 6
    },
    {
      "x": 12,
      "y": 10,
      "z": 8,
      "materialId": 1,
      "energy": 0.1,
      "energyType": 6
    },
    {
      "x": 5,
      "y": 11,
      "z": 2,
      "materialId": 3,
      "energy": 0.36,
      "energyType": 0
    },
    {
      "x": 6,
      "y": 11,
      "z": 2,
      "materialId": 3,
      "energy": 0.36,
      "energyType": 0
    },
    {
      "x": 7,
      "y": 11,
      "z": 2,
      "materialId": 3,
      "energy": 0.36,
      "energyType": 0
    },
    {
      "x": 8,
      "y": 11,
      "z": 2,
      "materialId": 3,
      "energy": 0.36,
      "energyType": 0
    },
    {
      "x": 9,
      "y": 11,
      "z": 2,
      "materialId": 3,
      "energy": 0.36,
      "energyType": 0
    },
    {
      "x": 10,
      "y": 11,
      "z": 2,
      "materialId": 3,
      "energy": 0.36,
      "energyType": 0
    },
    {
      "x": 11,
      "y": 11,
      "z": 2,
      "materialId": 3,
      "energy": 0.36,
      "energyType": 0
    },
    {
      "x": 12,
      "y": 11,
      "z": 2,
      "materialId": 3,
      "energy": 0.36,
      "energyType": 0
    },
    {
      "x": 2,
      "y": 11,
      "z": 3,
      "materialId": 3,
      "energy": 0.32,
      "energyType": 2
    },
    {
      "x": 3,
      "y": 11,
      "z": 3,
      "materialId": 3,
      "energy": 0.32,
      "energyType": 2
    },
    {
      "x": 4,
      "y": 11,
      "z": 3,
      "materialId": 3,
      "energy": 0.32,
      "energyType": 2
    },
    {
      "x": 5,
      "y": 11,
      "z": 3,
      "materialId": 3,
      "energy": 0.36,
      "energyType": 0
    },
    {
      "x": 6,
      "y": 11,
      "z": 3,
      "materialId": 3,
      "energy": 0.36,
      "energyType": 0
    },
    {
      "x": 7,
      "y": 11,
      "z": 3,
      "materialId": 3,
      "energy": 0.36,
      "energyType": 0
    },
    {
      "x": 8,
      "y": 11,
      "z": 3,
      "materialId": 3,
      "energy": 0.36,
      "energyType": 0
    },
    {
      "x": 9,
      "y": 11,
      "z": 3,
      "materialId": 3,
      "energy": 0.36,
      "energyType": 0
    },
    {
      "x": 10,
      "y": 11,
      "z": 3,
      "materialId": 3,
      "energy": 0.36,
      "energyType": 0
    },
    {
      "x": 11,
      "y": 11,
      "z": 3,
      "materialId": 3,
      "energy": 0.36,
      "energyType": 0
    },
    {
      "x": 12,
      "y": 11,
      "z": 3,
      "materialId": 3,
      "energy": 0.36,
      "energyType": 0
    },
    {
      "x": 13,
      "y": 11,
      "z": 3,
      "materialId": 2,
      "energy": 0.25,
      "energyType": 2
    },
    {
      "x": 2,
      "y": 11,
      "z": 4,
      "materialId": 3,
      "energy": 0.32,
      "energyType": 2
    },
    {
      "x": 3,
      "y": 11,
      "z": 4,
      "materialId": 3,
      "energy": 0.32,
      "energyType": 2
    },
    {
      "x": 4,
      "y": 11,
      "z": 4,
      "materialId": 3,
      "energy": 0.32,
      "energyType": 2
    },
    {
      "x": 5,
      "y": 11,
      "z": 4,
      "materialId": 2,
      "energy": 0.25,
      "energyType": 2
    },
    {
      "x": 6,
      "y": 11,
      "z": 4,
      "materialId": 2,
      "energy": 0.25,
      "energyType": 2
    },
    {
      "x": 7,
      "y": 11,
      "z": 4,
      "materialId": 2,
      "energy": 0.25,
      "energyType": 2
    },
    {
      "x": 8,
      "y": 11,
      "z": 4,
      "materialId": 2,
      "energy": 0.25,
      "energyType": 2
    },
    {
      "x": 9,
      "y": 11,
      "z": 4,
      "materialId": 2,
      "energy": 0.25,
      "energyType": 2
    },
    {
      "x": 10,
      "y": 11,
      "z": 4,
      "materialId": 2,
      "energy": 0.25,
      "energyType": 2
    },
    {
      "x": 11,
      "y": 11,
      "z": 4,
      "materialId": 2,
      "energy": 0.25,
      "energyType": 2
    },
    {
      "x": 12,
      "y": 11,
      "z": 4,
      "materialId": 2,
      "energy": 0.25,
      "energyType": 2
    },
    {
      "x": 13,
      "y": 11,
      "z": 4,
      "materialId": 3,
      "energy": 0.28,
      "energyType": 2
    },
    {
      "x": 14,
      "y": 11,
      "z": 4,
      "materialId": 3,
      "energy": 0.28,
      "energyType": 2
    },
    {
      "x": 15,
      "y": 11,
      "z": 4,
      "materialId": 3,
      "energy": 0.28,
      "energyType": 2
    },
    {
      "x": 2,
      "y": 11,
      "z": 5,
      "materialId": 3,
      "energy": 0.32,
      "energyType": 2
    },
    {
      "x": 3,
      "y": 11,
      "z": 5,
      "materialId": 3,
      "energy": 0.32,
      "energyType": 2
    },
    {
      "x": 4,
      "y": 11,
      "z": 5,
      "materialId": 3,
      "energy": 0.32,
      "energyType": 2
    },
    {
      "x": 5,
      "y": 11,
      "z": 5,
      "materialId": 2,
      "energy": 0.25,
      "energyType": 2
    },
    {
      "x": 6,
      "y": 11,
      "z": 5,
      "materialId": 2,
      "energy": 0.25,
      "energyType": 2
    },
    {
      "x": 7,
      "y": 11,
      "z": 5,
      "materialId": 2,
      "energy": 0.25,
      "energyType": 2
    },
    {
      "x": 8,
      "y": 11,
      "z": 5,
      "materialId": 2,
      "energy": 0.25,
      "energyType": 2
    },
    {
      "x": 9,
      "y": 11,
      "z": 5,
      "materialId": 2,
      "energy": 0.25,
      "energyType": 2
    },
    {
      "x": 10,
      "y": 11,
      "z": 5,
      "materialId": 2,
      "energy": 0.25,
      "energyType": 2
    },
    {
      "x": 11,
      "y": 11,
      "z": 5,
      "materialId": 2,
      "energy": 0.25,
      "energyType": 2
    },
    {
      "x": 12,
      "y": 11,
      "z": 5,
      "materialId": 2,
      "energy": 0.25,
      "energyType": 2
    },
    {
      "x": 13,
      "y": 11,
      "z": 5,
      "materialId": 3,
      "energy": 0.28,
      "energyType": 2
    },
    {
      "x": 14,
      "y": 11,
      "z": 5,
      "materialId": 3,
      "energy": 0.28,
      "energyType": 2
    },
    {
      "x": 15,
      "y": 11,
      "z": 5,
      "materialId": 3,
      "energy": 0.28,
      "energyType": 2
    },
    {
      "x": 4,
      "y": 11,
      "z": 6,
      "materialId": 2,
      "energy": 0.25,
      "energyType": 2
    },
    {
      "x": 5,
      "y": 11,
      "z": 6,
      "materialId": 2,
      "energy": 0.25,
      "energyType": 2
    },
    {
      "x": 6,
      "y": 11,
      "z": 6,
      "materialId": 2,
      "energy": 0.25,
      "energyType": 2
    },
    {
      "x": 7,
      "y": 11,
      "z": 6,
      "materialId": 2,
      "energy": 0.25,
      "energyType": 2
    },
    {
      "x": 8,
      "y": 11,
      "z": 6,
      "materialId": 2,
      "energy": 0.25,
      "energyType": 2
    },
    {
      "x": 9,
      "y": 11,
      "z": 6,
      "materialId": 2,
      "energy": 0.25,
      "energyType": 2
    },
    {
      "x": 10,
      "y": 11,
      "z": 6,
      "materialId": 2,
      "energy": 0.25,
      "energyType": 2
    },
    {
      "x": 11,
      "y": 11,
      "z": 6,
      "materialId": 2,
      "energy": 0.25,
      "energyType": 2
    },
    {
      "x": 12,
      "y": 11,
      "z": 6,
      "materialId": 2,
      "energy": 0.25,
      "energyType": 2
    },
    {
      "x": 13,
      "y": 11,
      "z": 6,
      "materialId": 3,
      "energy": 0.28,
      "energyType": 2
    },
    {
      "x": 14,
      "y": 11,
      "z": 6,
      "materialId": 3,
      "energy": 0.28,
      "energyType": 2
    },
    {
      "x": 15,
      "y": 11,
      "z": 6,
      "materialId": 3,
      "energy": 0.28,
      "energyType": 2
    },
    {
      "x": 5,
      "y": 11,
      "z": 7,
      "materialId": 1,
      "energy": 0.1,
      "energyType": 6
    },
    {
      "x": 6,
      "y": 11,
      "z": 7,
      "materialId": 1,
      "energy": 0.1,
      "energyType": 6
    },
    {
      "x": 7,
      "y": 11,
      "z": 7,
      "materialId": 1,
      "energy": 0.1,
      "energyType": 6
    },
    {
      "x": 8,
      "y": 11,
      "z": 7,
      "materialId": 1,
      "energy": 0.1,
      "energyType": 6
    },
    {
      "x": 9,
      "y": 11,
      "z": 7,
      "materialId": 1,
      "energy": 0.1,
      "energyType": 6
    },
    {
      "x": 10,
      "y": 11,
      "z": 7,
      "materialId": 1,
      "energy": 0.1,
      "energyType": 6
    },
    {
      "x": 11,
      "y": 11,
      "z": 7,
      "materialId": 1,
      "energy": 0.1,
      "energyType": 6
    },
    {
      "x": 12,
      "y": 11,
      "z": 7,
      "materialId": 1,
      "energy": 0.1,
      "energyType": 6
    },
    {
      "x": 5,
      "y": 11,
      "z": 8,
      "materialId": 1,
      "energy": 0.1,
      "energyType": 6
    },
    {
      "x": 6,
      "y": 11,
      "z": 8,
      "materialId": 1,
      "energy": 0.1,
      "energyType": 6
    },
    {
      "x": 7,
      "y": 11,
      "z": 8,
      "materialId": 1,
      "energy": 0.1,
      "energyType": 6
    },
    {
      "x": 8,
      "y": 11,
      "z": 8,
      "materialId": 1,
      "energy": 0.1,
      "energyType": 6
    },
    {
      "x": 9,
      "y": 11,
      "z": 8,
      "materialId": 1,
      "energy": 0.1,
      "energyType": 6
    },
    {
      "x": 10,
      "y": 11,
      "z": 8,
      "materialId": 1,
      "energy": 0.1,
      "energyType": 6
    },
    {
      "x": 11,
      "y": 11,
      "z": 8,
      "materialId": 1,
      "energy": 0.1,
      "energyType": 6
    },
    {
      "x": 12,
      "y": 11,
      "z": 8,
      "materialId": 1,
      "energy": 0.1,
      "energyType": 6
    },
    {
      "x": 8,
      "y": 12,
      "z": 2,
      "materialId": 3,
      "energy": 0.4,
      "energyType": 0
    },
    {
      "x": 9,
      "y": 12,
      "z": 2,
      "materialId": 3,
      "energy": 0.4,
      "energyType": 0
    },
    {
      "x": 2,
      "y": 12,
      "z": 3,
      "materialId": 3,
      "energy": 0.32,
      "energyType": 2
    },
    {
      "x": 3,
      "y": 12,
      "z": 3,
      "materialId": 3,
      "energy": 0.32,
      "energyType": 2
    },
    {
      "x": 4,
      "y": 12,
      "z": 3,
      "materialId": 3,
      "energy": 0.32,
      "energyType": 2
    },
    {
      "x": 5,
      "y": 12,
      "z": 3,
      "materialId": 2,
      "energy": 0.25,
      "energyType": 2
    },
    {
      "x": 6,
      "y": 12,
      "z": 3,
      "materialId": 2,
      "energy": 0.25,
      "energyType": 2
    },
    {
      "x": 7,
      "y": 12,
      "z": 3,
      "materialId": 2,
      "energy": 0.25,
      "energyType": 2
    },
    {
      "x": 8,
      "y": 12,
      "z": 3,
      "materialId": 2,
      "energy": 0.25,
      "energyType": 2
    },
    {
      "x": 9,
      "y": 12,
      "z": 3,
      "materialId": 2,
      "energy": 0.25,
      "energyType": 2
    },
    {
      "x": 10,
      "y": 12,
      "z": 3,
      "materialId": 2,
      "energy": 0.25,
      "energyType": 2
    },
    {
      "x": 11,
      "y": 12,
      "z": 3,
      "materialId": 2,
      "energy": 0.25,
      "energyType": 2
    },
    {
      "x": 12,
      "y": 12,
      "z": 3,
      "materialId": 2,
      "energy": 0.25,
      "energyType": 2
    },
    {
      "x": 13,
      "y": 12,
      "z": 3,
      "materialId": 2,
      "energy": 0.25,
      "energyType": 2
    },
    {
      "x": 2,
      "y": 12,
      "z": 4,
      "materialId": 3,
      "energy": 0.32,
      "energyType": 2
    },
    {
      "x": 3,
      "y": 12,
      "z": 4,
      "materialId": 3,
      "energy": 0.32,
      "energyType": 2
    },
    {
      "x": 4,
      "y": 12,
      "z": 4,
      "materialId": 3,
      "energy": 0.32,
      "energyType": 2
    },
    {
      "x": 5,
      "y": 12,
      "z": 4,
      "materialId": 2,
      "energy": 0.25,
      "energyType": 2
    },
    {
      "x": 6,
      "y": 12,
      "z": 4,
      "materialId": 2,
      "energy": 0.25,
      "energyType": 2
    },
    {
      "x": 7,
      "y": 12,
      "z": 4,
      "materialId": 2,
      "energy": 0.25,
      "energyType": 2
    },
    {
      "x": 8,
      "y": 12,
      "z": 4,
      "materialId": 2,
      "energy": 0.25,
      "energyType": 2
    },
    {
      "x": 9,
      "y": 12,
      "z": 4,
      "materialId": 2,
      "energy": 0.25,
      "energyType": 2
    },
    {
      "x": 10,
      "y": 12,
      "z": 4,
      "materialId": 2,
      "energy": 0.25,
      "energyType": 2
    },
    {
      "x": 11,
      "y": 12,
      "z": 4,
      "materialId": 2,
      "energy": 0.25,
      "energyType": 2
    },
    {
      "x": 12,
      "y": 12,
      "z": 4,
      "materialId": 2,
      "energy": 0.25,
      "energyType": 2
    },
    {
      "x": 13,
      "y": 12,
      "z": 4,
      "materialId": 3,
      "energy": 0.28,
      "energyType": 2
    },
    {
      "x": 14,
      "y": 12,
      "z": 4,
      "materialId": 3,
      "energy": 0.28,
      "energyType": 2
    },
    {
      "x": 15,
      "y": 12,
      "z": 4,
      "materialId": 3,
      "energy": 0.28,
      "energyType": 2
    },
    {
      "x": 2,
      "y": 12,
      "z": 5,
      "materialId": 3,
      "energy": 0.32,
      "energyType": 2
    },
    {
      "x": 3,
      "y": 12,
      "z": 5,
      "materialId": 3,
      "energy": 0.32,
      "energyType": 2
    },
    {
      "x": 4,
      "y": 12,
      "z": 5,
      "materialId": 3,
      "energy": 0.32,
      "energyType": 2
    },
    {
      "x": 5,
      "y": 12,
      "z": 5,
      "materialId": 2,
      "energy": 0.25,
      "energyType": 2
    },
    {
      "x": 6,
      "y": 12,
      "z": 5,
      "materialId": 2,
      "energy": 0.25,
      "energyType": 2
    },
    {
      "x": 7,
      "y": 12,
      "z": 5,
      "materialId": 2,
      "energy": 0.25,
      "energyType": 2
    },
    {
      "x": 8,
      "y": 12,
      "z": 5,
      "materialId": 2,
      "energy": 0.25,
      "energyType": 2
    },
    {
      "x": 9,
      "y": 12,
      "z": 5,
      "materialId": 2,
      "energy": 0.25,
      "energyType": 2
    },
    {
      "x": 10,
      "y": 12,
      "z": 5,
      "materialId": 2,
      "energy": 0.25,
      "energyType": 2
    },
    {
      "x": 11,
      "y": 12,
      "z": 5,
      "materialId": 2,
      "energy": 0.25,
      "energyType": 2
    },
    {
      "x": 12,
      "y": 12,
      "z": 5,
      "materialId": 2,
      "energy": 0.25,
      "energyType": 2
    },
    {
      "x": 13,
      "y": 12,
      "z": 5,
      "materialId": 3,
      "energy": 0.28,
      "energyType": 2
    },
    {
      "x": 14,
      "y": 12,
      "z": 5,
      "materialId": 3,
      "energy": 0.28,
      "energyType": 2
    },
    {
      "x": 15,
      "y": 12,
      "z": 5,
      "materialId": 3,
      "energy": 0.28,
      "energyType": 2
    },
    {
      "x": 4,
      "y": 12,
      "z": 6,
      "materialId": 2,
      "energy": 0.25,
      "energyType": 2
    },
    {
      "x": 5,
      "y": 12,
      "z": 6,
      "materialId": 2,
      "energy": 0.25,
      "energyType": 2
    },
    {
      "x": 6,
      "y": 12,
      "z": 6,
      "materialId": 2,
      "energy": 0.25,
      "energyType": 2
    },
    {
      "x": 7,
      "y": 12,
      "z": 6,
      "materialId": 2,
      "energy": 0.25,
      "energyType": 2
    },
    {
      "x": 8,
      "y": 12,
      "z": 6,
      "materialId": 2,
      "energy": 0.25,
      "energyType": 2
    },
    {
      "x": 9,
      "y": 12,
      "z": 6,
      "materialId": 2,
      "energy": 0.25,
      "energyType": 2
    },
    {
      "x": 10,
      "y": 12,
      "z": 6,
      "materialId": 2,
      "energy": 0.25,
      "energyType": 2
    },
    {
      "x": 11,
      "y": 12,
      "z": 6,
      "materialId": 2,
      "energy": 0.25,
      "energyType": 2
    },
    {
      "x": 12,
      "y": 12,
      "z": 6,
      "materialId": 2,
      "energy": 0.25,
      "energyType": 2
    },
    {
      "x": 13,
      "y": 12,
      "z": 6,
      "materialId": 3,
      "energy": 0.28,
      "energyType": 2
    },
    {
      "x": 14,
      "y": 12,
      "z": 6,
      "materialId": 3,
      "energy": 0.28,
      "energyType": 2
    },
    {
      "x": 15,
      "y": 12,
      "z": 6,
      "materialId": 3,
      "energy": 0.28,
      "energyType": 2
    },
    {
      "x": 5,
      "y": 12,
      "z": 7,
      "materialId": 1,
      "energy": 0.1,
      "energyType": 6
    },
    {
      "x": 6,
      "y": 12,
      "z": 7,
      "materialId": 1,
      "energy": 0.1,
      "energyType": 6
    },
    {
      "x": 7,
      "y": 12,
      "z": 7,
      "materialId": 1,
      "energy": 0.1,
      "energyType": 6
    },
    {
      "x": 8,
      "y": 12,
      "z": 7,
      "materialId": 1,
      "energy": 0.1,
      "energyType": 6
    },
    {
      "x": 9,
      "y": 12,
      "z": 7,
      "materialId": 1,
      "energy": 0.1,
      "energyType": 6
    },
    {
      "x": 10,
      "y": 12,
      "z": 7,
      "materialId": 1,
      "energy": 0.1,
      "energyType": 6
    },
    {
      "x": 11,
      "y": 12,
      "z": 7,
      "materialId": 1,
      "energy": 0.1,
      "energyType": 6
    },
    {
      "x": 12,
      "y": 12,
      "z": 7,
      "materialId": 1,
      "energy": 0.1,
      "energyType": 6
    },
    {
      "x": 5,
      "y": 12,
      "z": 8,
      "materialId": 1,
      "energy": 0.1,
      "energyType": 6
    },
    {
      "x": 6,
      "y": 12,
      "z": 8,
      "materialId": 1,
      "energy": 0.1,
      "energyType": 6
    },
    {
      "x": 7,
      "y": 12,
      "z": 8,
      "materialId": 1,
      "energy": 0.1,
      "energyType": 6
    },
    {
      "x": 8,
      "y": 12,
      "z": 8,
      "materialId": 1,
      "energy": 0.1,
      "energyType": 6
    },
    {
      "x": 9,
      "y": 12,
      "z": 8,
      "materialId": 1,
      "energy": 0.1,
      "energyType": 6
    },
    {
      "x": 10,
      "y": 12,
      "z": 8,
      "materialId": 1,
      "energy": 0.1,
      "energyType": 6
    },
    {
      "x": 11,
      "y": 12,
      "z": 8,
      "materialId": 1,
      "energy": 0.1,
      "energyType": 6
    },
    {
      "x": 12,
      "y": 12,
      "z": 8,
      "materialId": 1,
      "energy": 0.1,
      "energyType": 6
    },
    {
      "x": 8,
      "y": 13,
      "z": 2,
      "materialId": 4,
      "energy": 0.7,
      "energyType": 0
    },
    {
      "x": 9,
      "y": 13,
      "z": 2,
      "materialId": 4,
      "energy": 0.7,
      "energyType": 0
    },
    {
      "x": 2,
      "y": 13,
      "z": 3,
      "materialId": 2,
      "energy": 0.2,
      "energyType": 2
    },
    {
      "x": 3,
      "y": 13,
      "z": 3,
      "materialId": 2,
      "energy": 0.2,
      "energyType": 2
    },
    {
      "x": 4,
      "y": 13,
      "z": 3,
      "materialId": 2,
      "energy": 0.2,
      "energyType": 2
    },
    {
      "x": 5,
      "y": 13,
      "z": 3,
      "materialId": 2,
      "energy": 0.25,
      "energyType": 2
    },
    {
      "x": 6,
      "y": 13,
      "z": 3,
      "materialId": 2,
      "energy": 0.25,
      "energyType": 2
    },
    {
      "x": 7,
      "y": 13,
      "z": 3,
      "materialId": 2,
      "energy": 0.25,
      "energyType": 2
    },
    {
      "x": 8,
      "y": 13,
      "z": 3,
      "materialId": 2,
      "energy": 0.25,
      "energyType": 2
    },
    {
      "x": 9,
      "y": 13,
      "z": 3,
      "materialId": 2,
      "energy": 0.25,
      "energyType": 2
    },
    {
      "x": 10,
      "y": 13,
      "z": 3,
      "materialId": 2,
      "energy": 0.25,
      "energyType": 2
    },
    {
      "x": 11,
      "y": 13,
      "z": 3,
      "materialId": 2,
      "energy": 0.25,
      "energyType": 2
    },
    {
      "x": 12,
      "y": 13,
      "z": 3,
      "materialId": 2,
      "energy": 0.25,
      "energyType": 2
    },
    {
      "x": 13,
      "y": 13,
      "z": 3,
      "materialId": 2,
      "energy": 0.25,
      "energyType": 2
    },
    {
      "x": 2,
      "y": 13,
      "z": 4,
      "materialId": 2,
      "energy": 0.2,
      "energyType": 2
    },
    {
      "x": 3,
      "y": 13,
      "z": 4,
      "materialId": 2,
      "energy": 0.2,
      "energyType": 2
    },
    {
      "x": 4,
      "y": 13,
      "z": 4,
      "materialId": 2,
      "energy": 0.2,
      "energyType": 2
    },
    {
      "x": 5,
      "y": 13,
      "z": 4,
      "materialId": 2,
      "energy": 0.25,
      "energyType": 2
    },
    {
      "x": 6,
      "y": 13,
      "z": 4,
      "materialId": 2,
      "energy": 0.25,
      "energyType": 2
    },
    {
      "x": 7,
      "y": 13,
      "z": 4,
      "materialId": 2,
      "energy": 0.25,
      "energyType": 2
    },
    {
      "x": 8,
      "y": 13,
      "z": 4,
      "materialId": 2,
      "energy": 0.25,
      "energyType": 2
    },
    {
      "x": 9,
      "y": 13,
      "z": 4,
      "materialId": 2,
      "energy": 0.25,
      "energyType": 2
    },
    {
      "x": 10,
      "y": 13,
      "z": 4,
      "materialId": 2,
      "energy": 0.25,
      "energyType": 2
    },
    {
      "x": 11,
      "y": 13,
      "z": 4,
      "materialId": 2,
      "energy": 0.25,
      "energyType": 2
    },
    {
      "x": 12,
      "y": 13,
      "z": 4,
      "materialId": 2,
      "energy": 0.25,
      "energyType": 2
    },
    {
      "x": 13,
      "y": 13,
      "z": 4,
      "materialId": 2,
      "energy": 0.2,
      "energyType": 2
    },
    {
      "x": 14,
      "y": 13,
      "z": 4,
      "materialId": 2,
      "energy": 0.2,
      "energyType": 2
    },
    {
      "x": 15,
      "y": 13,
      "z": 4,
      "materialId": 2,
      "energy": 0.2,
      "energyType": 2
    },
    {
      "x": 2,
      "y": 13,
      "z": 5,
      "materialId": 2,
      "energy": 0.2,
      "energyType": 2
    },
    {
      "x": 3,
      "y": 13,
      "z": 5,
      "materialId": 2,
      "energy": 0.2,
      "energyType": 2
    },
    {
      "x": 4,
      "y": 13,
      "z": 5,
      "materialId": 2,
      "energy": 0.2,
      "energyType": 2
    },
    {
      "x": 5,
      "y": 13,
      "z": 5,
      "materialId": 2,
      "energy": 0.25,
      "energyType": 2
    },
    {
      "x": 6,
      "y": 13,
      "z": 5,
      "materialId": 2,
      "energy": 0.25,
      "energyType": 2
    },
    {
      "x": 7,
      "y": 13,
      "z": 5,
      "materialId": 2,
      "energy": 0.25,
      "energyType": 2
    },
    {
      "x": 8,
      "y": 13,
      "z": 5,
      "materialId": 2,
      "energy": 0.25,
      "energyType": 2
    },
    {
      "x": 9,
      "y": 13,
      "z": 5,
      "materialId": 2,
      "energy": 0.25,
      "energyType": 2
    },
    {
      "x": 10,
      "y": 13,
      "z": 5,
      "materialId": 2,
      "energy": 0.25,
      "energyType": 2
    },
    {
      "x": 11,
      "y": 13,
      "z": 5,
      "materialId": 2,
      "energy": 0.25,
      "energyType": 2
    },
    {
      "x": 12,
      "y": 13,
      "z": 5,
      "materialId": 2,
      "energy": 0.25,
      "energyType": 2
    },
    {
      "x": 13,
      "y": 13,
      "z": 5,
      "materialId": 2,
      "energy": 0.2,
      "energyType": 2
    },
    {
      "x": 14,
      "y": 13,
      "z": 5,
      "materialId": 2,
      "energy": 0.2,
      "energyType": 2
    },
    {
      "x": 15,
      "y": 13,
      "z": 5,
      "materialId": 2,
      "energy": 0.2,
      "energyType": 2
    },
    {
      "x": 4,
      "y": 13,
      "z": 6,
      "materialId": 2,
      "energy": 0.25,
      "energyType": 2
    },
    {
      "x": 5,
      "y": 13,
      "z": 6,
      "materialId": 2,
      "energy": 0.25,
      "energyType": 2
    },
    {
      "x": 6,
      "y": 13,
      "z": 6,
      "materialId": 2,
      "energy": 0.25,
      "energyType": 2
    },
    {
      "x": 7,
      "y": 13,
      "z": 6,
      "materialId": 2,
      "energy": 0.25,
      "energyType": 2
    },
    {
      "x": 8,
      "y": 13,
      "z": 6,
      "materialId": 2,
      "energy": 0.25,
      "energyType": 2
    },
    {
      "x": 9,
      "y": 13,
      "z": 6,
      "materialId": 2,
      "energy": 0.25,
      "energyType": 2
    },
    {
      "x": 10,
      "y": 13,
      "z": 6,
      "materialId": 2,
      "energy": 0.25,
      "energyType": 2
    },
    {
      "x": 11,
      "y": 13,
      "z": 6,
      "materialId": 2,
      "energy": 0.25,
      "energyType": 2
    },
    {
      "x": 12,
      "y": 13,
      "z": 6,
      "materialId": 2,
      "energy": 0.25,
      "energyType": 2
    },
    {
      "x": 13,
      "y": 13,
      "z": 6,
      "materialId": 2,
      "energy": 0.2,
      "energyType": 2
    },
    {
      "x": 14,
      "y": 13,
      "z": 6,
      "materialId": 2,
      "energy": 0.2,
      "energyType": 2
    },
    {
      "x": 15,
      "y": 13,
      "z": 6,
      "materialId": 2,
      "energy": 0.2,
      "energyType": 2
    },
    {
      "x": 5,
      "y": 13,
      "z": 7,
      "materialId": 1,
      "energy": 0.1,
      "energyType": 6
    },
    {
      "x": 6,
      "y": 13,
      "z": 7,
      "materialId": 1,
      "energy": 0.1,
      "energyType": 6
    },
    {
      "x": 7,
      "y": 13,
      "z": 7,
      "materialId": 1,
      "energy": 0.1,
      "energyType": 6
    },
    {
      "x": 8,
      "y": 13,
      "z": 7,
      "materialId": 1,
      "energy": 0.1,
      "energyType": 6
    },
    {
      "x": 9,
      "y": 13,
      "z": 7,
      "materialId": 1,
      "energy": 0.1,
      "energyType": 6
    },
    {
      "x": 10,
      "y": 13,
      "z": 7,
      "materialId": 1,
      "energy": 0.1,
      "energyType": 6
    },
    {
      "x": 11,
      "y": 13,
      "z": 7,
      "materialId": 1,
      "energy": 0.1,
      "energyType": 6
    },
    {
      "x": 12,
      "y": 13,
      "z": 7,
      "materialId": 1,
      "energy": 0.1,
      "energyType": 6
    },
    {
      "x": 5,
      "y": 13,
      "z": 8,
      "materialId": 1,
      "energy": 0.1,
      "energyType": 6
    },
    {
      "x": 6,
      "y": 13,
      "z": 8,
      "materialId": 1,
      "energy": 0.1,
      "energyType": 6
    },
    {
      "x": 7,
      "y": 13,
      "z": 8,
      "materialId": 1,
      "energy": 0.1,
      "energyType": 6
    },
    {
      "x": 8,
      "y": 13,
      "z": 8,
      "materialId": 1,
      "energy": 0.1,
      "energyType": 6
    },
    {
      "x": 9,
      "y": 13,
      "z": 8,
      "materialId": 1,
      "energy": 0.1,
      "energyType": 6
    },
    {
      "x": 10,
      "y": 13,
      "z": 8,
      "materialId": 1,
      "energy": 0.1,
      "energyType": 6
    },
    {
      "x": 11,
      "y": 13,
      "z": 8,
      "materialId": 1,
      "energy": 0.1,
      "energyType": 6
    },
    {
      "x": 12,
      "y": 13,
      "z": 8,
      "materialId": 1,
      "energy": 0.1,
      "energyType": 6
    },
    {
      "x": 8,
      "y": 14,
      "z": 2,
      "materialId": 3,
      "energy": 0.4,
      "energyType": 0
    },
    {
      "x": 9,
      "y": 14,
      "z": 2,
      "materialId": 3,
      "energy": 0.4,
      "energyType": 0
    },
    {
      "x": 2,
      "y": 14,
      "z": 3,
      "materialId": 2,
      "energy": 0.2,
      "energyType": 2
    },
    {
      "x": 3,
      "y": 14,
      "z": 3,
      "materialId": 2,
      "energy": 0.2,
      "energyType": 2
    },
    {
      "x": 4,
      "y": 14,
      "z": 3,
      "materialId": 2,
      "energy": 0.2,
      "energyType": 2
    },
    {
      "x": 5,
      "y": 14,
      "z": 3,
      "materialId": 2,
      "energy": 0.25,
      "energyType": 2
    },
    {
      "x": 6,
      "y": 14,
      "z": 3,
      "materialId": 2,
      "energy": 0.25,
      "energyType": 2
    },
    {
      "x": 7,
      "y": 14,
      "z": 3,
      "materialId": 2,
      "energy": 0.25,
      "energyType": 2
    },
    {
      "x": 8,
      "y": 14,
      "z": 3,
      "materialId": 2,
      "energy": 0.25,
      "energyType": 2
    },
    {
      "x": 9,
      "y": 14,
      "z": 3,
      "materialId": 2,
      "energy": 0.25,
      "energyType": 2
    },
    {
      "x": 10,
      "y": 14,
      "z": 3,
      "materialId": 2,
      "energy": 0.25,
      "energyType": 2
    },
    {
      "x": 11,
      "y": 14,
      "z": 3,
      "materialId": 2,
      "energy": 0.25,
      "energyType": 2
    },
    {
      "x": 12,
      "y": 14,
      "z": 3,
      "materialId": 2,
      "energy": 0.25,
      "energyType": 2
    },
    {
      "x": 13,
      "y": 14,
      "z": 3,
      "materialId": 2,
      "energy": 0.25,
      "energyType": 2
    },
    {
      "x": 2,
      "y": 14,
      "z": 4,
      "materialId": 2,
      "energy": 0.2,
      "energyType": 2
    },
    {
      "x": 3,
      "y": 14,
      "z": 4,
      "materialId": 2,
      "energy": 0.2,
      "energyType": 2
    },
    {
      "x": 4,
      "y": 14,
      "z": 4,
      "materialId": 2,
      "energy": 0.2,
      "energyType": 2
    },
    {
      "x": 5,
      "y": 14,
      "z": 4,
      "materialId": 2,
      "energy": 0.25,
      "energyType": 2
    },
    {
      "x": 6,
      "y": 14,
      "z": 4,
      "materialId": 2,
      "energy": 0.25,
      "energyType": 2
    },
    {
      "x": 7,
      "y": 14,
      "z": 4,
      "materialId": 2,
      "energy": 0.25,
      "energyType": 2
    },
    {
      "x": 8,
      "y": 14,
      "z": 4,
      "materialId": 2,
      "energy": 0.25,
      "energyType": 2
    },
    {
      "x": 9,
      "y": 14,
      "z": 4,
      "materialId": 2,
      "energy": 0.25,
      "energyType": 2
    },
    {
      "x": 10,
      "y": 14,
      "z": 4,
      "materialId": 2,
      "energy": 0.25,
      "energyType": 2
    },
    {
      "x": 11,
      "y": 14,
      "z": 4,
      "materialId": 2,
      "energy": 0.25,
      "energyType": 2
    },
    {
      "x": 12,
      "y": 14,
      "z": 4,
      "materialId": 2,
      "energy": 0.25,
      "energyType": 2
    },
    {
      "x": 13,
      "y": 14,
      "z": 4,
      "materialId": 2,
      "energy": 0.2,
      "energyType": 2
    },
    {
      "x": 14,
      "y": 14,
      "z": 4,
      "materialId": 2,
      "energy": 0.2,
      "energyType": 2
    },
    {
      "x": 15,
      "y": 14,
      "z": 4,
      "materialId": 2,
      "energy": 0.2,
      "energyType": 2
    },
    {
      "x": 2,
      "y": 14,
      "z": 5,
      "materialId": 2,
      "energy": 0.2,
      "energyType": 2
    },
    {
      "x": 3,
      "y": 14,
      "z": 5,
      "materialId": 2,
      "energy": 0.2,
      "energyType": 2
    },
    {
      "x": 4,
      "y": 14,
      "z": 5,
      "materialId": 2,
      "energy": 0.2,
      "energyType": 2
    },
    {
      "x": 5,
      "y": 14,
      "z": 5,
      "materialId": 2,
      "energy": 0.25,
      "energyType": 2
    },
    {
      "x": 6,
      "y": 14,
      "z": 5,
      "materialId": 2,
      "energy": 0.25,
      "energyType": 2
    },
    {
      "x": 7,
      "y": 14,
      "z": 5,
      "materialId": 2,
      "energy": 0.25,
      "energyType": 2
    },
    {
      "x": 8,
      "y": 14,
      "z": 5,
      "materialId": 2,
      "energy": 0.25,
      "energyType": 2
    },
    {
      "x": 9,
      "y": 14,
      "z": 5,
      "materialId": 2,
      "energy": 0.25,
      "energyType": 2
    },
    {
      "x": 10,
      "y": 14,
      "z": 5,
      "materialId": 2,
      "energy": 0.25,
      "energyType": 2
    },
    {
      "x": 11,
      "y": 14,
      "z": 5,
      "materialId": 2,
      "energy": 0.25,
      "energyType": 2
    },
    {
      "x": 12,
      "y": 14,
      "z": 5,
      "materialId": 2,
      "energy": 0.25,
      "energyType": 2
    },
    {
      "x": 13,
      "y": 14,
      "z": 5,
      "materialId": 2,
      "energy": 0.2,
      "energyType": 2
    },
    {
      "x": 14,
      "y": 14,
      "z": 5,
      "materialId": 2,
      "energy": 0.2,
      "energyType": 2
    },
    {
      "x": 15,
      "y": 14,
      "z": 5,
      "materialId": 2,
      "energy": 0.2,
      "energyType": 2
    },
    {
      "x": 4,
      "y": 14,
      "z": 6,
      "materialId": 2,
      "energy": 0.25,
      "energyType": 2
    },
    {
      "x": 5,
      "y": 14,
      "z": 6,
      "materialId": 2,
      "energy": 0.25,
      "energyType": 2
    },
    {
      "x": 6,
      "y": 14,
      "z": 6,
      "materialId": 2,
      "energy": 0.25,
      "energyType": 2
    },
    {
      "x": 7,
      "y": 14,
      "z": 6,
      "materialId": 2,
      "energy": 0.25,
      "energyType": 2
    },
    {
      "x": 8,
      "y": 14,
      "z": 6,
      "materialId": 2,
      "energy": 0.25,
      "energyType": 2
    },
    {
      "x": 9,
      "y": 14,
      "z": 6,
      "materialId": 2,
      "energy": 0.25,
      "energyType": 2
    },
    {
      "x": 10,
      "y": 14,
      "z": 6,
      "materialId": 2,
      "energy": 0.25,
      "energyType": 2
    },
    {
      "x": 11,
      "y": 14,
      "z": 6,
      "materialId": 2,
      "energy": 0.25,
      "energyType": 2
    },
    {
      "x": 12,
      "y": 14,
      "z": 6,
      "materialId": 2,
      "energy": 0.25,
      "energyType": 2
    },
    {
      "x": 13,
      "y": 14,
      "z": 6,
      "materialId": 2,
      "energy": 0.2,
      "energyType": 2
    },
    {
      "x": 14,
      "y": 14,
      "z": 6,
      "materialId": 2,
      "energy": 0.2,
      "energyType": 2
    },
    {
      "x": 15,
      "y": 14,
      "z": 6,
      "materialId": 2,
      "energy": 0.2,
      "energyType": 2
    },
    {
      "x": 5,
      "y": 14,
      "z": 7,
      "materialId": 1,
      "energy": 0.1,
      "energyType": 6
    },
    {
      "x": 6,
      "y": 14,
      "z": 7,
      "materialId": 1,
      "energy": 0.1,
      "energyType": 6
    },
    {
      "x": 7,
      "y": 14,
      "z": 7,
      "materialId": 1,
      "energy": 0.1,
      "energyType": 6
    },
    {
      "x": 8,
      "y": 14,
      "z": 7,
      "materialId": 1,
      "energy": 0.1,
      "energyType": 6
    },
    {
      "x": 9,
      "y": 14,
      "z": 7,
      "materialId": 1,
      "energy": 0.1,
      "energyType": 6
    },
    {
      "x": 10,
      "y": 14,
      "z": 7,
      "materialId": 1,
      "energy": 0.1,
      "energyType": 6
    },
    {
      "x": 11,
      "y": 14,
      "z": 7,
      "materialId": 1,
      "energy": 0.1,
      "energyType": 6
    },
    {
      "x": 12,
      "y": 14,
      "z": 7,
      "materialId": 1,
      "energy": 0.1,
      "energyType": 6
    },
    {
      "x": 5,
      "y": 14,
      "z": 8,
      "materialId": 1,
      "energy": 0.1,
      "energyType": 6
    },
    {
      "x": 6,
      "y": 14,
      "z": 8,
      "materialId": 1,
      "energy": 0.1,
      "energyType": 6
    },
    {
      "x": 7,
      "y": 14,
      "z": 8,
      "materialId": 1,
      "energy": 0.1,
      "energyType": 6
    },
    {
      "x": 8,
      "y": 14,
      "z": 8,
      "materialId": 1,
      "energy": 0.1,
      "energyType": 6
    },
    {
      "x": 9,
      "y": 14,
      "z": 8,
      "materialId": 1,
      "energy": 0.1,
      "energyType": 6
    },
    {
      "x": 10,
      "y": 14,
      "z": 8,
      "materialId": 1,
      "energy": 0.1,
      "energyType": 6
    },
    {
      "x": 11,
      "y": 14,
      "z": 8,
      "materialId": 1,
      "energy": 0.1,
      "energyType": 6
    },
    {
      "x": 12,
      "y": 14,
      "z": 8,
      "materialId": 1,
      "energy": 0.1,
      "energyType": 6
    },
    {
      "x": 8,
      "y": 15,
      "z": 2,
      "materialId": 3,
      "energy": 0.4,
      "energyType": 0
    },
    {
      "x": 9,
      "y": 15,
      "z": 2,
      "materialId": 3,
      "energy": 0.4,
      "energyType": 0
    },
    {
      "x": 2,
      "y": 15,
      "z": 3,
      "materialId": 2,
      "energy": 0.2,
      "energyType": 2
    },
    {
      "x": 3,
      "y": 15,
      "z": 3,
      "materialId": 2,
      "energy": 0.2,
      "energyType": 2
    },
    {
      "x": 4,
      "y": 15,
      "z": 3,
      "materialId": 2,
      "energy": 0.2,
      "energyType": 2
    },
    {
      "x": 5,
      "y": 15,
      "z": 3,
      "materialId": 2,
      "energy": 0.25,
      "energyType": 2
    },
    {
      "x": 6,
      "y": 15,
      "z": 3,
      "materialId": 2,
      "energy": 0.25,
      "energyType": 2
    },
    {
      "x": 7,
      "y": 15,
      "z": 3,
      "materialId": 2,
      "energy": 0.25,
      "energyType": 2
    },
    {
      "x": 8,
      "y": 15,
      "z": 3,
      "materialId": 2,
      "energy": 0.25,
      "energyType": 2
    },
    {
      "x": 9,
      "y": 15,
      "z": 3,
      "materialId": 2,
      "energy": 0.25,
      "energyType": 2
    },
    {
      "x": 10,
      "y": 15,
      "z": 3,
      "materialId": 2,
      "energy": 0.25,
      "energyType": 2
    },
    {
      "x": 11,
      "y": 15,
      "z": 3,
      "materialId": 2,
      "energy": 0.25,
      "energyType": 2
    },
    {
      "x": 12,
      "y": 15,
      "z": 3,
      "materialId": 2,
      "energy": 0.25,
      "energyType": 2
    },
    {
      "x": 13,
      "y": 15,
      "z": 3,
      "materialId": 2,
      "energy": 0.25,
      "energyType": 2
    },
    {
      "x": 14,
      "y": 15,
      "z": 3,
      "materialId": 2,
      "energy": 0.25,
      "energyType": 2
    },
    {
      "x": 2,
      "y": 15,
      "z": 4,
      "materialId": 2,
      "energy": 0.2,
      "energyType": 2
    },
    {
      "x": 3,
      "y": 15,
      "z": 4,
      "materialId": 2,
      "energy": 0.2,
      "energyType": 2
    },
    {
      "x": 4,
      "y": 15,
      "z": 4,
      "materialId": 2,
      "energy": 0.2,
      "energyType": 2
    },
    {
      "x": 5,
      "y": 15,
      "z": 4,
      "materialId": 2,
      "energy": 0.25,
      "energyType": 2
    },
    {
      "x": 6,
      "y": 15,
      "z": 4,
      "materialId": 2,
      "energy": 0.25,
      "energyType": 2
    },
    {
      "x": 7,
      "y": 15,
      "z": 4,
      "materialId": 2,
      "energy": 0.25,
      "energyType": 2
    },
    {
      "x": 8,
      "y": 15,
      "z": 4,
      "materialId": 2,
      "energy": 0.25,
      "energyType": 2
    },
    {
      "x": 9,
      "y": 15,
      "z": 4,
      "materialId": 2,
      "energy": 0.25,
      "energyType": 2
    },
    {
      "x": 10,
      "y": 15,
      "z": 4,
      "materialId": 2,
      "energy": 0.25,
      "energyType": 2
    },
    {
      "x": 11,
      "y": 15,
      "z": 4,
      "materialId": 2,
      "energy": 0.25,
      "energyType": 2
    },
    {
      "x": 12,
      "y": 15,
      "z": 4,
      "materialId": 2,
      "energy": 0.25,
      "energyType": 2
    },
    {
      "x": 13,
      "y": 15,
      "z": 4,
      "materialId": 2,
      "energy": 0.2,
      "energyType": 2
    },
    {
      "x": 14,
      "y": 15,
      "z": 4,
      "materialId": 2,
      "energy": 0.2,
      "energyType": 2
    },
    {
      "x": 15,
      "y": 15,
      "z": 4,
      "materialId": 2,
      "energy": 0.2,
      "energyType": 2
    },
    {
      "x": 2,
      "y": 15,
      "z": 5,
      "materialId": 2,
      "energy": 0.2,
      "energyType": 2
    },
    {
      "x": 3,
      "y": 15,
      "z": 5,
      "materialId": 2,
      "energy": 0.2,
      "energyType": 2
    },
    {
      "x": 4,
      "y": 15,
      "z": 5,
      "materialId": 2,
      "energy": 0.2,
      "energyType": 2
    },
    {
      "x": 5,
      "y": 15,
      "z": 5,
      "materialId": 2,
      "energy": 0.25,
      "energyType": 2
    },
    {
      "x": 6,
      "y": 15,
      "z": 5,
      "materialId": 2,
      "energy": 0.25,
      "energyType": 2
    },
    {
      "x": 7,
      "y": 15,
      "z": 5,
      "materialId": 2,
      "energy": 0.25,
      "energyType": 2
    },
    {
      "x": 8,
      "y": 15,
      "z": 5,
      "materialId": 2,
      "energy": 0.25,
      "energyType": 2
    },
    {
      "x": 9,
      "y": 15,
      "z": 5,
      "materialId": 2,
      "energy": 0.25,
      "energyType": 2
    },
    {
      "x": 10,
      "y": 15,
      "z": 5,
      "materialId": 2,
      "energy": 0.25,
      "energyType": 2
    },
    {
      "x": 11,
      "y": 15,
      "z": 5,
      "materialId": 2,
      "energy": 0.25,
      "energyType": 2
    },
    {
      "x": 12,
      "y": 15,
      "z": 5,
      "materialId": 2,
      "energy": 0.25,
      "energyType": 2
    },
    {
      "x": 13,
      "y": 15,
      "z": 5,
      "materialId": 2,
      "energy": 0.2,
      "energyType": 2
    },
    {
      "x": 14,
      "y": 15,
      "z": 5,
      "materialId": 2,
      "energy": 0.2,
      "energyType": 2
    },
    {
      "x": 15,
      "y": 15,
      "z": 5,
      "materialId": 2,
      "energy": 0.2,
      "energyType": 2
    },
    {
      "x": 3,
      "y": 15,
      "z": 6,
      "materialId": 2,
      "energy": 0.25,
      "energyType": 2
    },
    {
      "x": 4,
      "y": 15,
      "z": 6,
      "materialId": 2,
      "energy": 0.25,
      "energyType": 2
    },
    {
      "x": 5,
      "y": 15,
      "z": 6,
      "materialId": 2,
      "energy": 0.25,
      "energyType": 2
    },
    {
      "x": 6,
      "y": 15,
      "z": 6,
      "materialId": 2,
      "energy": 0.25,
      "energyType": 2
    },
    {
      "x": 7,
      "y": 15,
      "z": 6,
      "materialId": 2,
      "energy": 0.25,
      "energyType": 2
    },
    {
      "x": 8,
      "y": 15,
      "z": 6,
      "materialId": 2,
      "energy": 0.25,
      "energyType": 2
    },
    {
      "x": 9,
      "y": 15,
      "z": 6,
      "materialId": 2,
      "energy": 0.25,
      "energyType": 2
    },
    {
      "x": 10,
      "y": 15,
      "z": 6,
      "materialId": 2,
      "energy": 0.25,
      "energyType": 2
    },
    {
      "x": 11,
      "y": 15,
      "z": 6,
      "materialId": 2,
      "energy": 0.25,
      "energyType": 2
    },
    {
      "x": 12,
      "y": 15,
      "z": 6,
      "materialId": 2,
      "energy": 0.25,
      "energyType": 2
    },
    {
      "x": 13,
      "y": 15,
      "z": 6,
      "materialId": 2,
      "energy": 0.2,
      "energyType": 2
    },
    {
      "x": 14,
      "y": 15,
      "z": 6,
      "materialId": 2,
      "energy": 0.2,
      "energyType": 2
    },
    {
      "x": 15,
      "y": 15,
      "z": 6,
      "materialId": 2,
      "energy": 0.2,
      "energyType": 2
    },
    {
      "x": 5,
      "y": 15,
      "z": 7,
      "materialId": 1,
      "energy": 0.1,
      "energyType": 6
    },
    {
      "x": 6,
      "y": 15,
      "z": 7,
      "materialId": 1,
      "energy": 0.1,
      "energyType": 6
    },
    {
      "x": 7,
      "y": 15,
      "z": 7,
      "materialId": 1,
      "energy": 0.1,
      "energyType": 6
    },
    {
      "x": 8,
      "y": 15,
      "z": 7,
      "materialId": 1,
      "energy": 0.1,
      "energyType": 6
    },
    {
      "x": 9,
      "y": 15,
      "z": 7,
      "materialId": 1,
      "energy": 0.1,
      "energyType": 6
    },
    {
      "x": 10,
      "y": 15,
      "z": 7,
      "materialId": 1,
      "energy": 0.1,
      "energyType": 6
    },
    {
      "x": 11,
      "y": 15,
      "z": 7,
      "materialId": 1,
      "energy": 0.1,
      "energyType": 6
    },
    {
      "x": 12,
      "y": 15,
      "z": 7,
      "materialId": 1,
      "energy": 0.1,
      "energyType": 6
    },
    {
      "x": 5,
      "y": 15,
      "z": 8,
      "materialId": 1,
      "energy": 0.1,
      "energyType": 6
    },
    {
      "x": 6,
      "y": 15,
      "z": 8,
      "materialId": 1,
      "energy": 0.1,
      "energyType": 6
    },
    {
      "x": 7,
      "y": 15,
      "z": 8,
      "materialId": 1,
      "energy": 0.1,
      "energyType": 6
    },
    {
      "x": 8,
      "y": 15,
      "z": 8,
      "materialId": 1,
      "energy": 0.1,
      "energyType": 6
    },
    {
      "x": 9,
      "y": 15,
      "z": 8,
      "materialId": 1,
      "energy": 0.1,
      "energyType": 6
    },
    {
      "x": 10,
      "y": 15,
      "z": 8,
      "materialId": 1,
      "energy": 0.1,
      "energyType": 6
    },
    {
      "x": 11,
      "y": 15,
      "z": 8,
      "materialId": 1,
      "energy": 0.1,
      "energyType": 6
    },
    {
      "x": 12,
      "y": 15,
      "z": 8,
      "materialId": 1,
      "energy": 0.1,
      "energyType": 6
    },
    {
      "x": 8,
      "y": 16,
      "z": 2,
      "materialId": 4,
      "energy": 0.7,
      "energyType": 0
    },
    {
      "x": 9,
      "y": 16,
      "z": 2,
      "materialId": 4,
      "energy": 0.7,
      "energyType": 0
    },
    {
      "x": 2,
      "y": 16,
      "z": 3,
      "materialId": 2,
      "energy": 0.2,
      "energyType": 2
    },
    {
      "x": 3,
      "y": 16,
      "z": 3,
      "materialId": 2,
      "energy": 0.2,
      "energyType": 2
    },
    {
      "x": 4,
      "y": 16,
      "z": 3,
      "materialId": 2,
      "energy": 0.2,
      "energyType": 2
    },
    {
      "x": 5,
      "y": 16,
      "z": 3,
      "materialId": 2,
      "energy": 0.25,
      "energyType": 2
    },
    {
      "x": 6,
      "y": 16,
      "z": 3,
      "materialId": 2,
      "energy": 0.25,
      "energyType": 2
    },
    {
      "x": 7,
      "y": 16,
      "z": 3,
      "materialId": 2,
      "energy": 0.25,
      "energyType": 2
    },
    {
      "x": 8,
      "y": 16,
      "z": 3,
      "materialId": 2,
      "energy": 0.25,
      "energyType": 2
    },
    {
      "x": 9,
      "y": 16,
      "z": 3,
      "materialId": 2,
      "energy": 0.25,
      "energyType": 2
    },
    {
      "x": 10,
      "y": 16,
      "z": 3,
      "materialId": 2,
      "energy": 0.25,
      "energyType": 2
    },
    {
      "x": 11,
      "y": 16,
      "z": 3,
      "materialId": 2,
      "energy": 0.25,
      "energyType": 2
    },
    {
      "x": 12,
      "y": 16,
      "z": 3,
      "materialId": 2,
      "energy": 0.25,
      "energyType": 2
    },
    {
      "x": 13,
      "y": 16,
      "z": 3,
      "materialId": 2,
      "energy": 0.25,
      "energyType": 2
    },
    {
      "x": 14,
      "y": 16,
      "z": 3,
      "materialId": 2,
      "energy": 0.25,
      "energyType": 2
    },
    {
      "x": 2,
      "y": 16,
      "z": 4,
      "materialId": 2,
      "energy": 0.2,
      "energyType": 2
    },
    {
      "x": 3,
      "y": 16,
      "z": 4,
      "materialId": 2,
      "energy": 0.2,
